Workbook

Sheet Tamis
A1: échantillon | B1: Annee | C1: masse totale (g) | D1: 4000 | E1: 2000 | F1: 1700 | G1: 1000 | H1: 840 | I1: 500 | J1: 420 | K1: 210 | L1: 125 | M1: 105 | N1: 63 | O1: <63 | P1: 4000_pct | Q1: 2000_pct | R1: 1700_pct | S1: 1000_pct | T1: 840_pct | U1: 500_pct | V1: 420_pct | W1: 210_pct | X1: 125_pct | Y1: 105_pct | Z1: 63_pct | AA1: <63_pct | AB1: pct<500
A2: baie-01 | B2: 2022 | C2: 29.66 | D2: 0 | E2: 0.03 | F2: 0.02 | G2: 0.15 | H2: 0.12 | I2: 0.7 | J2: 0.48 | K2: 4.47 | L2: 16.45 | M2: 2.82 | N2: 3.28 | O2: 1.08 | P2: =(D2/C2)*100 -> 0 | Q2: =(E2/C2)*100 -> 0.10114633 | R2: =(F2/C2)*100 -> 0.067430883 | S2: =(G2/C2)*100 -> 0.50573163 | T2: =(H2/C2)*100 -> 0.4045853 | U2: =(I2/C2)*100 -> 2.3600809 | V2: =(J2/C2)*100 -> 1.6183412 | W2: =(K2/C2)*100 -> 15.070802 | X2: =(L2/C2)*100 -> 55.461902 | Y2: =(M2/C2)*100 -> 9.5077546 | Z2: =(N2/C2)*100 -> 11.058665 | AA2: =(O2/C2)*100 -> 3.6412677 | AB2: =SUM(V2:AA2) -> 96.358732 | AC2: =SUM(P2:AA2) -> 99.797707
A3: baie-02 | B3: 2022 | C3: 20.55 | D3: 0 | E3: 0.05 | F3: 0 | G3: 0.14 | H3: 0 | I3: 0.33 | J3: 0.24 | K3: 4.92 | L3: 6.07 | M3: 4.92 | N3: 2.9 | O3: 0.64 | P3: =(D3/C3)*100 -> 0 | Q3: =(E3/C3)*100 -> 0.243309 | R3: =(F3/C3)*100 -> 0 | S3: =(G3/C3)*100 -> 0.68126521 | T3: =(H3/C3)*100 -> 0 | U3: =(I3/C3)*100 -> 1.6058394 | V3: =(J3/C3)*100 -> 1.1678832 | W3: =(K3/C3)*100 -> 23.941606 | X3: =(L3/C3)*100 -> 29.537713 | Y3: =(M3/C3)*100 -> 23.941606 | Z3: =(N3/C3)*100 -> 14.111922 | AA3: =(O3/C3)*100 -> 3.1143552 | AB3: =SUM(V3:AA3) -> 95.815085 | AC3: =SUM(P3:AA3) -> 98.345499
A4: baie-04 | B4: 2022 | C4: 26.43 | D4: 0 | E4: 0 | F4: 0.06 | G4: 0.16 | H4: 0.02 | I4: 0.51 | J4: 0.27 | K4: 4.5 | L4: 13.15 | M4: 3.21 | N4: 3.81 | O4: 0.7 | P4: =(D4/C4)*100 -> 0 | Q4: =(E4/C4)*100 -> 0 | R4: =(F4/C4)*100 -> 0.22701476 | S4: =(G4/C4)*100 -> 0.60537268 | T4: =(H4/C4)*100 -> 0.075671585 | U4: =(I4/C4)*100 -> 1.9296254 | V4: =(J4/C4)*100 -> 1.0215664 | W4: =(K4/C4)*100 -> 17.026107 | X4: =(L4/C4)*100 -> 49.754067 | Y4: =(M4/C4)*100 -> 12.145289 | Z4: =(N4/C4)*100 -> 14.415437 | AA4: =(O4/C4)*100 -> 2.6485055 | AB4: =SUM(V4:AA4) -> 97.010972 | AC4: =SUM(P4:AA4) -> 99.848657
A5: baie-05 | B5: 2022 | C5: 19.84 | D5: 0.28 | E5: 0.01 | F5: 0 | G5: 0.05 | H5: 0.01 | I5: 0.94 | J5: 0.65 | K5: 4.65 | L5: 7.43 | M5: 2.38 | N5: 2.66 | O5: 0.64 | P5: =(D5/C5)*100 -> 1.4112903 | Q5: =(E5/C5)*100 -> 0.050403226 | R5: =(F5/C5)*100 -> 0 | S5: =(G5/C5)*100 -> 0.25201613 | T5: =(H5/C5)*100 -> 0.050403226 | U5: =(I5/C5)*100 -> 4.7379032 | V5: =(J5/C5)*100 -> 3.2762097 | W5: =(K5/C5)*100 -> 23.4375 | X5: =(L5/C5)*100 -> 37.449597 | Y5: =(M5/C5)*100 -> 11.995968 | Z5: =(N5/C5)*100 -> 13.407258 | AA5: =(O5/C5)*100 -> 3.2258065 | AB5: =SUM(V5:AA5) -> 92.792339 | AC5: =SUM(P5:AA5) -> 99.294355
A6: baie-06 | B6: 2022 | C6: 68.68 | D6: 1.28 | E6: 0.43 | F6: 0.34 | G6: 1.2 | H6: 0.19 | I6: 6.62 | J6: 3.92 | K6: 22.86 | L6: 20.16 | M6: 6.21 | N6: 4.76 | O6: 0.55 | P6: =(D6/C6)*100 -> 1.8637158 | Q6: =(E6/C6)*100 -> 0.62609202 | R6: =(F6/C6)*100 -> 0.4950495 | S6: =(G6/C6)*100 -> 1.7472335 | T6: =(H6/C6)*100 -> 0.27664531 | U6: =(I6/C6)*100 -> 9.6389051 | V6: =(J6/C6)*100 -> 5.7076296 | W6: =(K6/C6)*100 -> 33.284799 | X6: =(L6/C6)*100 -> 29.353524 | Y6: =(M6/C6)*100 -> 9.0419336 | Z6: =(N6/C6)*100 -> 6.9306931 | AA6: =(O6/C6)*100 -> 0.80081538 | AB6: =SUM(V6:AA6) -> 85.119394 | AC6: =SUM(P6:AA6) -> 99.767036
A7: baie-08 | B7: 2022 | C7: 14.76 | D7: 0 | E7: 0 | F7: 0.01 | G7: 0.17 | H7: 0.02 | I7: 0.72 | J7: 0.51 | K7: 3.39 | L7: 4.78 | M7: 1.99 | N7: 2.3 | O7: 0.68 | P7: =(D7/C7)*100 -> 0 | Q7: =(E7/C7)*100 -> 0 | R7: =(F7/C7)*100 -> 0.067750678 | S7: =(G7/C7)*100 -> 1.1517615 | T7: =(H7/C7)*100 -> 0.13550136 | U7: =(I7/C7)*100 -> 4.8780488 | V7: =(J7/C7)*100 -> 3.4552846 | W7: =(K7/C7)*100 -> 22.96748 | X7: =(L7/C7)*100 -> 32.384824 | Y7: =(M7/C7)*100 -> 13.482385 | Z7: =(N7/C7)*100 -> 15.582656 | AA7: =(O7/C7)*100 -> 4.6070461 | AB7: =SUM(V7:AA7) -> 92.479675 | AC7: =SUM(P7:AA7) -> 98.712737
A8: baie-09 | B8: 2022 | C8: 48.44 | D8: 0 | E8: 0.1 | F8: 0.12 | G8: 1.16 | H8: 0.05 | I8: 3.32 | J8: 1.11 | K8: 13.36 | L8: 14.24 | M8: 6.34 | N8: 6.7 | O8: 1.66 | P8: =(D8/C8)*100 -> 0 | Q8: =(E8/C8)*100 -> 0.20644096 | R8: =(F8/C8)*100 -> 0.24772915 | S8: =(G8/C8)*100 -> 2.3947151 | T8: =(H8/C8)*100 -> 0.10322048 | U8: =(I8/C8)*100 -> 6.8538398 | V8: =(J8/C8)*100 -> 2.2914946 | W8: =(K8/C8)*100 -> 27.580512 | X8: =(L8/C8)*100 -> 29.397192 | Y8: =(M8/C8)*100 -> 13.088357 | Z8: =(N8/C8)*100 -> 13.831544 | AA8: =(O8/C8)*100 -> 3.4269199 | AB8: =SUM(V8:AA8) -> 89.61602 | AC8: =SUM(P8:AA8) -> 99.421965
A9: baie-10 | B9: 2022 | C9: 62.43 | D9: 0.07 | E9: 0.13 | F9: 0.1 | G9: 1.58 | H9: 0.09 | I9: 7.99 | J9: 3.3 | K9: 25.05 | L9: 14.42 | M9: 3.84 | N9: 4.39 | O9: 1.17 | P9: =(D9/C9)*100 -> 0.11212558 | Q9: =(E9/C9)*100 -> 0.20823322 | R9: =(F9/C9)*100 -> 0.1601794 | S9: =(G9/C9)*100 -> 2.5308345 | T9: =(H9/C9)*100 -> 0.14416146 | U9: =(I9/C9)*100 -> 12.798334 | V9: =(J9/C9)*100 -> 5.2859202 | W9: =(K9/C9)*100 -> 40.12494 | X9: =(L9/C9)*100 -> 23.09787 | Y9: =(M9/C9)*100 -> 6.150889 | Z9: =(N9/C9)*100 -> 7.0318757 | AA9: =(O9/C9)*100 -> 1.874099 | AB9: =SUM(V9:AA9) -> 83.565593 | AC9: =SUM(P9:AA9) -> 99.519462
A10: baie-11 | B10: 2022 | C10: 34.11 | D10: 0 | E10: 0 | F10: 0.02 | G10: 0.11 | H10: 0 | I10: 0.29 | J10: 0.27 | K10: 16.23 | L10: 14.46 | M10: 0.88 | N10: 1.27 | O10: 0.51 | P10: =(D10/C10)*100 -> 0 | Q10: =(E10/C10)*100 -> 0 | R10: =(F10/C10)*100 -> 0.058633832 | S10: =(G10/C10)*100 -> 0.32248607 | T10: =(H10/C10)*100 -> 0 | U10: =(I10/C10)*100 -> 0.85019056 | V10: =(J10/C10)*100 -> 0.79155673 | W10: =(K10/C10)*100 -> 47.581354 | X10: =(L10/C10)*100 -> 42.39226 | Y10: =(M10/C10)*100 -> 2.5798886 | Z10: =(N10/C10)*100 -> 3.7232483 | AA10: =(O10/C10)*100 -> 1.4951627 | AB10: =SUM(V10:AA10) -> 98.563471 | AC10: =SUM(P10:AA10) -> 99.794782
A11: baie-15 | B11: 2022 | C11: 29.16 | D11: 1.83 | E11: 0.02 | F11: 0.07 | G11: 0.41 | H11: 0.15 | I11: 1.37 | J11: 0.93 | K11: 13.83 | L11: 7.17 | M11: 1.79 | N11: 1.3 | O11: 0.18 | P11: =(D11/C11)*100 -> 6.2757202 | Q11: =(E11/C11)*100 -> 0.068587106 | R11: =(F11/C11)*100 -> 0.24005487 | S11: =(G11/C11)*100 -> 1.4060357 | T11: =(H11/C11)*100 -> 0.51440329 | U11: =(I11/C11)*100 -> 4.6982167 | V11: =(J11/C11)*100 -> 3.1893004 | W11: =(K11/C11)*100 -> 47.427984 | X11: =(L11/C11)*100 -> 24.588477 | Y11: =(M11/C11)*100 -> 6.138546 | Z11: =(N11/C11)*100 -> 4.4581619 | AA11: =(O11/C11)*100 -> 0.61728395 | AB11: =SUM(V11:AA11) -> 86.419753 | AC11: =SUM(P11:AA11) -> 99.622771
A12: baie-15.2 | B12: 2023 | C12: 15.29 | D12: 2.91 | E12: 0.03 | F12: 0.01 | G12: 0.13 | H12: 1.09 | I12: 0.07 | J12: 0.74 | K12: 4.1 | L12: 2.66 | M12: 0.52 | N12: 1.27 | O12: 1.7 | P12: =(D12/C12)*100 -> 19.032047 | Q12: =(E12/C12)*100 -> 0.19620667 | R12: =(F12/C12)*100 -> 0.065402224 | S12: =(G12/C12)*100 -> 0.85022891 | T12: =(H12/C12)*100 -> 7.1288424 | U12: =(I12/C12)*100 -> 0.45781557 | V12: =(J12/C12)*100 -> 4.8397646 | W12: =(K12/C12)*100 -> 26.814912 | X12: =(L12/C12)*100 -> 17.396991 | Y12: =(M12/C12)*100 -> 3.4009156 | Z12: =(N12/C12)*100 -> 8.3060824 | AA12: =(O12/C12)*100 -> 11.118378 | AB12: =SUM(V12:AA12) -> 71.877044 | AC12: =SUM(P12:AA12) -> 99.607587
A13: baie-16 | B13: 2022 | C13: 33.26 | D13: 0.59 | E13: 0.27 | F13: 0.08 | G13: 0.55 | H13: 0.03 | I13: 3.78 | J13: 1.75 | K13: 7.93 | L13: 8.95 | M13: 4.17 | N13: 3.91 | O13: 0.97 | P13: =(D13/C13)*100 -> 1.7739026 | Q13: =(E13/C13)*100 -> 0.81178593 | R13: =(F13/C13)*100 -> 0.24052916 | S13: =(G13/C13)*100 -> 1.653638 | T13: =(H13/C13)*100 -> 0.090198437 | U13: =(I13/C13)*100 -> 11.365003 | V13: =(J13/C13)*100 -> 5.2615755 | W13: =(K13/C13)*100 -> 23.842453 | X13: =(L13/C13)*100 -> 26.9092 | Y13: =(M13/C13)*100 -> 12.537583 | Z13: =(N13/C13)*100 -> 11.755863 | AA13: =(O13/C13)*100 -> 2.9164161 | AB13: =SUM(V13:AA13) -> 83.223091 | AC13: =SUM(P13:AA13) -> 99.158148
... A56: ce-16 | B56: 2022 | C56: 21.5 | D56: 0 | E56: 0.09 | F56: 0.02 | G56: 0.38 | H56: 2.14 | I56: 0.04 | J56: 1.52 | K56: 9.46 | L56: 3.28 | M56: 1.07 | N56: 2.53 | O56: 0.87 | P56: =(D56/C56)*100 -> 0 | Q56: =(E56/C56)*100 -> 0.41860465 | R56: =(F56/C56)*100 -> 0.093023256 | S56: =(G56/C56)*100 -> 1.7674419 | T56: =(H56/C56)*100 -> 9.9534884 | U56: =(I56/C56)*100 -> 0.18604651 | V56: =(J56/C56)*100 -> 7.0697674 | W56: =(K56/C56)*100 -> 44 | X56: =(L56/C56)*100 -> 15.255814 | Y56: =(M56/C56)*100 -> 4.9767442 | Z56: =(N56/C56)*100 -> 11.767442 | AA56: =(O56/C56)*100 -> 4.0465116 | AB56: =SUM(V56:AA56) -> 87.116279 | AC56: =SUM(P56:AA56) -> 99.534884
A57: ce-18 | B57: 2022 | C57: =SUM(D57:O57) -> 7.57 | D57: 0 | E57: 0 | F57: 0.01 | G57: 0.09 | H57: 1.27 | I57: 0.06 | J57: 0.61 | K57: 2.6 | L57: 1.36 | M57: 0.38 | N57: 0.68 | O57: 0.51 | P57: =(D57/C57)*100 -> 0 | Q57: =(E57/C57)*100 -> 0 | R57: =(F57/C57)*100 -> 0.1321004 | S57: =(G57/C57)*100 -> 1.1889036 | T57: =(H57/C57)*100 -> 16.77675 | U57: =(I57/C57)*100 -> 0.79260238 | V57: =(J57/C57)*100 -> 8.0581242 | W57: =(K57/C57)*100 -> 34.346103 | X57: =(L57/C57)*100 -> 17.965654 | Y57: =(M57/C57)*100 -> 5.0198151 | Z57: =(N57/C57)*100 -> 8.9828269 | AA57: =(O57/C57)*100 -> 6.7371202 | AB57: =SUM(V57:AA57) -> 81.109643 | AC57: =SUM(P57:AA57) -> 100
A58: ce-19 | B58: 2022 | C58: 33.15 | D58: 0 | E58: 0.15 | F58: 0.1 | G58: 1.01 | H58: 0.03 | I58: 2.67 | J58: 0.88 | K58: 9.46 | L58: 11.03 | M58: 2.64 | N58: 4.08 | O58: 1.15 | P58: =(D58/C58)*100 -> 0 | Q58: =(E58/C58)*100 -> 0.45248869 | R58: =(F58/C58)*100 -> 0.30165913 | S58: =(G58/C58)*100 -> 3.0467572 | T58: =(H58/C58)*100 -> 0.090497738 | U58: =(I58/C58)*100 -> 8.0542986 | V58: =(J58/C58)*100 -> 2.6546003 | W58: =(K58/C58)*100 -> 28.536953 | X58: =(L58/C58)*100 -> 33.273002 | Y58: =(M58/C58)*100 -> 7.9638009 | Z58: =(N58/C58)*100 -> 12.307692 | AA58: =(O58/C58)*100 -> 3.4690799 | AB58: =SUM(V58:AA58) -> 88.205128 | AC58: =SUM(P58:AA58) -> 100.15083
A59: ce-20 | B59: 2022 | C59: 45.83 | D59: 0 | E59: 0 | F59: 0 | G59: 0.23 | H59: 0.02 | I59: 1.13 | J59: 0.53 | K59: 3.26 | L59: 15.32 | M59: 10.88 | N59: 11.44 | O59: 2.72 | P59: =(D59/C59)*100 -> 0 | Q59: =(E59/C59)*100 -> 0 | R59: =(F59/C59)*100 -> 0 | S59: =(G59/C59)*100 -> 0.50185468 | T59: =(H59/C59)*100 -> 0.043639537 | U59: =(I59/C59)*100 -> 2.4656339 | V59: =(J59/C59)*100 -> 1.1564477 | W59: =(K59/C59)*100 -> 7.1132446 | X59: =(L59/C59)*100 -> 33.427886 | Y59: =(M59/C59)*100 -> 23.739908 | Z59: =(N59/C59)*100 -> 24.961815 | AA59: =(O59/C59)*100 -> 5.9349771 | AB59: =SUM(V59:AA59) -> 96.334279 | AC59: =SUM(P59:AA59) -> 99.345407
A60: ce-21 | B60: 2022 | C60: 46.78 | D60: 0 | E60: 0.03 | F60: 0.02 | G60: 0.2 | H60: 0.12 | I60: 0.75 | J60: 0.56 | K60: 25.26 | L60: 13.52 | M60: 1.36 | N60: 3.32 | O60: 1.11 | P60: =(D60/C60)*100 -> 0 | Q60: =(E60/C60)*100 -> 0.06412997 | R60: =(F60/C60)*100 -> 0.042753313 | S60: =(G60/C60)*100 -> 0.42753313 | T60: =(H60/C60)*100 -> 0.25651988 | U60: =(I60/C60)*100 -> 1.6032493 | V60: =(J60/C60)*100 -> 1.1970928 | W60: =(K60/C60)*100 -> 53.997435 | X60: =(L60/C60)*100 -> 28.90124 | Y60: =(M60/C60)*100 -> 2.9072253 | Z60: =(N60/C60)*100 -> 7.09705 | AA60: =(O60/C60)*100 -> 2.3728089 | AB60: =SUM(V60:AA60) -> 96.472852 | AC60: =SUM(P60:AA60) -> 98.867037
A61: ce-22 | B61: 2022 | C61: 15.4 | D61: 0 | E61: 0.05 | F61: 0.01 | G61: 0.62 | H61: 4.07 | I61: 0.1 | J61: 1.3 | K61: 4.76 | L61: 1.64 | M61: 0.57 | N61: 1.28 | O61: 0.89 | P61: =(D61/C61)*100 -> 0 | Q61: =(E61/C61)*100 -> 0.32467532 | R61: =(F61/C61)*100 -> 0.064935065 | S61: =(G61/C61)*100 -> 4.025974 | T61: =(H61/C61)*100 -> 26.428571 | U61: =(I61/C61)*100 -> 0.64935065 | V61: =(J61/C61)*100 -> 8.4415584 | W61: =(K61/C61)*100 -> 30.909091 | X61: =(L61/C61)*100 -> 10.649351 | Y61: =(M61/C61)*100 -> 3.7012987 | Z61: =(N61/C61)*100 -> 8.3116883 | AA61: =(O61/C61)*100 -> 5.7792208 | AB61: =SUM(V61:AA61) -> 67.792208 | AC61: =SUM(P61:AA61) -> 99.285714
A62: ce-23 | B62: 2022 | C62: 24.74 | D62: 0 | E62: 0 | F62: 0 | G62: 0.18 | H62: 0.08 | I62: 0.61 | J62: 0.57 | K62: 11.96 | L62: 7.97 | M62: 2 | N62: 1.24 | O62: 0.23 | P62: =(D62/C62)*100 -> 0 | Q62: =(E62/C62)*100 -> 0 | R62: =(F62/C62)*100 -> 0 | S62: =(G62/C62)*100 -> 0.72756669 | T62: =(H62/C62)*100 -> 0.32336297 | U62: =(I62/C62)*100 -> 2.4656427 | V62: =(J62/C62)*100 -> 2.3039612 | W62: =(K62/C62)*100 -> 48.342765 | X62: =(L62/C62)*100 -> 32.215036 | Y62: =(M62/C62)*100 -> 8.0840744 | Z62: =(N62/C62)*100 -> 5.0121261 | AA62: =(O62/C62)*100 -> 0.92966855 | AB62: =SUM(V62:AA62) -> 96.887631 | AC62: =SUM(P62:AA62) -> 100.4042
A63: ce-24 | B63: 2022 | C63: 12.83 | D63: 0.19 | E63: 0.09 | F63: 0.04 | G63: 0.25 | H63: 1.78 | I63: 0.01 | J63: 0.93 | K63: 4.16 | L63: 2.83 | M63: 0.47 | N63: 1.46 | O63: 0.55 | P63: =(D63/C63)*100 -> 1.4809041 | Q63: =(E63/C63)*100 -> 0.7014809 | R63: =(F63/C63)*100 -> 0.31176929 | S63: =(G63/C63)*100 -> 1.9485581 | T63: =(H63/C63)*100 -> 13.873733 | U63: =(I63/C63)*100 -> 0.077942323 | V63: =(J63/C63)*100 -> 7.248636 | W63: =(K63/C63)*100 -> 32.424006 | X63: =(L63/C63)*100 -> 22.057677 | Y63: =(M63/C63)*100 -> 3.6632892 | Z63: =(N63/C63)*100 -> 11.379579 | AA63: =(O63/C63)*100 -> 4.2868277 | AB63: =SUM(V63:AA63) -> 81.060016 | AC63: =SUM(P63:AA63) -> 99.454404
A64: ce-25 | B64: 2022 | C64: 23.48 | D64: 0.15 | E64: 0.08 | F64: 0 | G64: 0.22 | H64: 0.02 | I64: 2.7 | J64: 1.4 | K64: 7.21 | L64: 7.41 | M64: 1.97 | N64: 1.47 | O64: 0.79 | P64: =(D64/C64)*100 -> 0.63884157 | Q64: =(E64/C64)*100 -> 0.3407155 | R64: =(F64/C64)*100 -> 0 | S64: =(G64/C64)*100 -> 0.93696763 | T64: =(H64/C64)*100 -> 0.085178876 | U64: =(I64/C64)*100 -> 11.499148 | V64: =(J64/C64)*100 -> 5.9625213 | W64: =(K64/C64)*100 -> 30.706985 | X64: =(L64/C64)*100 -> 31.558773 | Y64: =(M64/C64)*100 -> 8.3901193 | Z64: =(N64/C64)*100 -> 6.2606474 | AA64: =(O64/C64)*100 -> 3.3645656 | AB64: =SUM(V64:AA64) -> 86.243612 | AC64: =SUM(P64:AA64) -> 99.744463
A65: ce-27 | B65: 2022 | C65: 58.87 | D65: 17.98 | E65: 3.98 | F65: 0.71 | G65: 3.99 | H65: 0.1 | I65: 8.76 | J65: 1.77 | K65: 7.38 | L65: 6.51 | M65: 2.18 | N65: 3.55 | O65: 1.73 | P65: =(D65/C65)*100 -> 30.541872 | Q65: =(E65/C65)*100 -> 6.7606591 | R65: =(F65/C65)*100 -> 1.2060472 | S65: =(G65/C65)*100 -> 6.7776457 | T65: =(H65/C65)*100 -> 0.16986581 | U65: =(I65/C65)*100 -> 14.880245 | V65: =(J65/C65)*100 -> 3.0066248 | W65: =(K65/C65)*100 -> 12.536096 | X65: =(L65/C65)*100 -> 11.058264 | Y65: =(M65/C65)*100 -> 3.7030746 | Z65: =(N65/C65)*100 -> 6.0302361 | AA65: =(O65/C65)*100 -> 2.9386784 | AB65: =SUM(V65:AA65) -> 39.272974 | AC65: =SUM(P65:AA65) -> 99.609309
A66: ce-28 | B66: 2022 | C66: 31.97 | D66: 1.15 | E66: 0.12 | F66: 0.03 | G66: 0.4 | H66: 0.03 | I66: 2.33 | J66: 1.08 | K66: 10.92 | L66: 10.54 | M66: 2.15 | N66: 2.56 | O66: 0.56 | P66: =(D66/C66)*100 -> 3.5971223 | Q66: =(E66/C66)*100 -> 0.37535189 | R66: =(F66/C66)*100 -> 0.093837973 | S66: =(G66/C66)*100 -> 1.251173 | T66: =(H66/C66)*100 -> 0.093837973 | U66: =(I66/C66)*100 -> 7.2880826 | V66: =(J66/C66)*100 -> 3.378167 | W66: =(K66/C66)*100 -> 34.157022 | X66: =(L66/C66)*100 -> 32.968408 | Y66: =(M66/C66)*100 -> 6.7250547 | Z66: =(N66/C66)*100 -> 8.007507 | AA66: =(O66/C66)*100 -> 1.7516422 | AB66: =SUM(V66:AA66) -> 86.987801 | AC66: =SUM(P66:AA66) -> 99.687207
A67: ce-30 | B67: 2022 | C67: 38.11 | D67: 0 | E67: 0.19 | F67: 0.14 | G67: 0.35 | H67: 0.13 | I67: 0.85 | J67: 0.59 | K67: 17.92 | L67: 12.45 | M67: 2.84 | N67: 2.27 | O67: 0.38 | P67: =(D67/C67)*100 -> 0 | Q67: =(E67/C67)*100 -> 0.49855681 | R67: =(F67/C67)*100 -> 0.36735765 | S67: =(G67/C67)*100 -> 0.91839412 | T67: =(H67/C67)*100 -> 0.34111782 | U67: =(I67/C67)*100 -> 2.2303857 | V67: =(J67/C67)*100 -> 1.5481501 | W67: =(K67/C67)*100 -> 47.021779 | X67: =(L67/C67)*100 -> 32.668591 | Y67: =(M67/C67)*100 -> 7.4521123 | Z67: =(N67/C67)*100 -> 5.9564419 | AA67: =(O67/C67)*100 -> 0.99711362 | AB67: =SUM(V67:AA67) -> 95.644188 | AC67: =SUM(P67:AA67) -> 100
A68: ce-31 | B68: 2022 | C68: 20.78 | D68: 0 | E68: 0 | F68: 0 | G68: 0.23 | H68: 0.01 | I68: 2.44 | J68: 0.94 | K68: 4.79 | L68: 8.53 | M68: 1.17 | N68: 2.16 | O68: 0.52 | P68: =(D68/C68)*100 -> 0 | Q68: =(E68/C68)*100 -> 0 | R68: =(F68/C68)*100 -> 0 | S68: =(G68/C68)*100 -> 1.1068335 | T68: =(H68/C68)*100 -> 0.048123195 | U68: =(I68/C68)*100 -> 11.74206 | V68: =(J68/C68)*100 -> 4.5235804 | W68: =(K68/C68)*100 -> 23.051011 | X68: =(L68/C68)*100 -> 41.049086 | Y68: =(M68/C68)*100 -> 5.6304139 | Z68: =(N68/C68)*100 -> 10.39461 | AA68: =(O68/C68)*100 -> 2.5024062 | AB68: =SUM(V68:AA68) -> 87.151107 | AC68: =SUM(P68:AA68) -> 100.04812
A69: ce-32 | B69: 2022 | C69: 25.82 | D69: 0.29 | E69: 0.04 | F69: 0.01 | G69: 0.2 | H69: 0.19 | I69: 1.15 | J69: 0.67 | K69: 12.45 | L69: 6.3 | M69: 2.67 | N69: 1.4 | O69: 0.27 | P69: =(D69/C69)*100 -> 1.1231603 | Q69: =(E69/C69)*100 -> 0.15491867 | R69: =(F69/C69)*100 -> 0.038729667 | S69: =(G69/C69)*100 -> 0.77459334 | T69: =(H69/C69)*100 -> 0.73586367 | U69: =(I69/C69)*100 -> 4.4539117 | V69: =(J69/C69)*100 -> 2.5948877 | W69: =(K69/C69)*100 -> 48.218435 | X69: =(L69/C69)*100 -> 24.39969 | Y69: =(M69/C69)*100 -> 10.340821 | Z69: =(N69/C69)*100 -> 5.4221534 | AA69: =(O69/C69)*100 -> 1.045701 | AB69: =SUM(V69:AA69) -> 92.021689 | AC69: =SUM(P69:AA69) -> 99.302866
... A101: fu-20 | B101: 2022 | C101: 105.51 | D101: 17 | E101: 13.79 | F101: 3.88 | G101: 27.22 | H101: 0.42 | I101: 34.04 | J101: 2 | K101: 6.14 | L101: 0.66 | M101: 0.05 | N101: 0.03 | O101: 0.01 | P101: =(D101/C101)*100 -> 16.112217 | Q101: =(E101/C101)*100 -> 13.069851 | R101: =(F101/C101)*100 -> 3.6773766 | S101: =(G101/C101)*100 -> 25.798503 | T101: =(H101/C101)*100 -> 0.39806653 | U101: =(I101/C101)*100 -> 32.262345 | V101: =(J101/C101)*100 -> 1.8955549 | W101: =(K101/C101)*100 -> 5.8193536 | X101: =(L101/C101)*100 -> 0.62553312 | Y101: =(M101/C101)*100 -> 0.047388873 | Z101: =(N101/C101)*100 -> 0.028433324 | AA101: =(O101/C101)*100 -> 0.0094777746 | AB101: =SUM(V101:AA101) -> 8.4257416 | AC101: =SUM(P101:AA101) -> 99.7441

Sheet Laser
A1: dia (um) | B1: fu-19 | C1: fu-01 | D1: fu-20 | E1: fu-16 | F1: fu-13 | G1: fu-14 | H1: fu-10 | I1: fu-11 | J1: fu-03 | K1: bint-11 | L1: bint-09 | M1: bint-12 | N1: bint-03 | O1: bint-05 | P1: baie-19 | Q1: baie-18 | R1: baie-16 | S1: baie-20 | T1: baie-10 | U1: baie-09 | V1: baie-11 | W1: baie-06 | X1: baie-08 | Y1: baie-04 | Z1: baie-01 | AA1: baie-05 | AB1: baie-02 | AC1: baie-15 | AD1: ce-46 | AE1: ce-47 | AF1: binf-08 | AG1: binf-01 | AH1: ce-50 | AI1: ce-48 | AJ1: binf-18 | AK1: binf-13 | AL1: ce-45 | AM1: binf-17 | AN1: ce-43 | AO1: ce-44 | AP1: ce-40 | AQ1: ce-42 | AR1: ce-37 | AS1: ce-39 | AT1: ce-34 | AU1: ce-36 | AV1: ce-32 | AW1: ce-33 | AX1: ce-30 | AY1: ce-31 | AZ1: ce-27 | BA1: ce-28 | BB1: ce-23 | BC1: ce-25 | BD1: ce-20 | BE1: ce-21 | BF1: ce-15 | BG1: ce-19 | BH1: ce-13 | BI1: ce-08 | BJ1: ce-14 | BK1: ce-06 | BL1: ce-09 | BM1: ce-04 | BN1: ce-07 | BO1: ce-05 | BP1: ce-01 | BQ1: ce-02 | BR1: binf-02 | BS1: ce-51 | BT1: binf-10 | BU1: ce-24 | BV1: binf-15 | BW1: ce-03 | BX1: fu-15 | BY1: ce-12 | BZ1: fu-12 | CA1: ce-16 | CB1: bint-14 | CC1: fu-05 | CD1: binf-04 | CE1: fu-18 | CF1: binf-20 | CG1: binf-05 | CH1: ce-08.2 | CI1: baie-15.2 | CJ1: bint-08 | CK1: fu-19.2 | CL1: fu-02 | CM1: fu-04 | CN1: ce-37.2 | CO1: ce-18 | CP1: ce-10 | CQ1: ce-22 | CR1: bint-15 | CS1: bint-02 | CT1: bint-06 | CU1: binf-18.2 | CV1: binf-07 | CW1: binf-12
A2: 0.011 | B2: 0 | C2: 0 | D2: 0 | E2: 0 | F2: 0 | G2: 0 | H2: 0 | I2: 0 | J2: 0 | K2: 0 | L2: 0 | M2: 0 | N2: 0 | O2: 0 | P2: 0 | Q2: 0 | R2: 0 | S2: 0 | T2: 0 | U2: 0 | V2: 0 | W2: 0 | X2: 0 | Y2: 0 | Z2: 0 | AA2: 0 | AB2: 0 | AC2: 0 | AD2: 0 | AE2: 0 | AF2: 0 | AG2: 0 | AH2: 0 | AI2: 0 | AJ2: 0 | AK2: 0 | AL2: 0 | AM2: 0 | AN2: 0 | AO2: 0 | AP2: 0 | AQ2: 0 | AR2: 0 | AS2: 0 | AT2: 0 | AU2: 0 | AV2: 0 | AW2: 0 | AX2: 0 | AY2: 0 | AZ2: 0 | BA2: 0 | BB2: 0 | BC2: 0 | BD2: 0 | BE2: 0 | BF2: 0 | BG2: 0 | BH2: 0 | BI2: 0 | BJ2: 0 | BK2: 0 | BL2: 0 | BM2: 0 | BN2: 0 | BO2: 0 | BP2: 0 | BQ2: 0 | BR2: 0 | BS2: 0 | BT2: 0 | BU2: 0 | BV2: 0 | BW2: 0 | BX2: 0 | BY2: 0 | BZ2: 0 | CA2: 0 | CB2: 0 | CC2: 0 | CD2: 0 | CE2: 0 | CF2: 0 | CG2: 0 | CH2: 0 | CI2: 0 | CJ2: 0 | CK2: 0 | CL2: 0 | CM2: 0 | CN2: 0 | CO2: 0 | CP2: 0 | CQ2: 0 | CR2: 0 | CS2: 0 | CT2: 0 | CU2: 0 | CV2: 0 | CW2: 0
A3: 0.013 | B3: 0 | C3: 0 | D3: 0 | E3: 0 | F3: 0 | G3: 0 | H3: 0 | I3: 0 | J3: 0 | K3: 0 | L3: 0 | M3: 0 | N3: 0 | O3: 0 | P3: 0 | Q3: 0 | R3: 0 | S3: 0 | T3: 0 | U3: 0 | V3: 0 | W3: 0 | X3: 0 | Y3: 0 | Z3: 0 | AA3: 0 | AB3: 0 | AC3: 0 | AD3: 0 | AE3: 0 | AF3: 0 | AG3: 0 | AH3: 0 | AI3: 0 | AJ3: 0 | AK3: 0 | AL3: 0 | AM3: 0 | AN3: 0 | AO3: 0 | AP3: 0 | AQ3: 0 | AR3: 0 | AS3: 0 | AT3: 0 | AU3: 0 | AV3: 0 | AW3: 0 | AX3: 0 | AY3: 0 | AZ3: 0 | BA3: 0 | BB3: 0 | BC3: 0 | BD3: 0 | BE3: 0 | BF3: 0 | BG3: 0 | BH3: 0 | BI3: 0 | BJ3: 0 | BK3: 0 | BL3: 0 | BM3: 0 | BN3: 0 | BO3: 0 | BP3: 0 | BQ3: 0 | BR3: 0 | BS3: 0 | BT3: 0 | BU3: 0 | BV3: 0 | BW3: 0 | BX3: 0 | BY3: 0 | BZ3: 0 | CA3: 0 | CB3: 0 | CC3: 0 | CD3: 0 | CE3: 0 | CF3: 0 | CG3: 0 | CH3: 0 | CI3: 0 | CJ3: 0 | CK3: 0 | CL3: 0 | CM3: 0 | CN3: 0 | CO3: 0 | CP3: 0 | CQ3: 0 | CR3: 0 | CS3: 0 | CT3: 0 | CU3: 0 | CV3: 0 | CW3: 0
A4: 0.015 | B4: 0 | C4: 0 | D4: 0 | E4: 0 | F4: 0 | G4: 0 | H4: 0 | I4: 0 | J4: 0 | K4: 0 | L4: 0 | M4: 0 | N4: 0 | O4: 0 | P4: 0 | Q4: 0 | R4: 0 | S4: 0 | T4: 0 | U4: 0 | V4: 0 | W4: 0 | X4: 0 | Y4: 0 | Z4: 0 | AA4: 0 | AB4: 0 | AC4: 0 | AD4: 0 | AE4: 0 | AF4: 0 | AG4: 0 | AH4: 0 | AI4: 0 | AJ4: 0 | AK4: 0 | AL4: 0 | AM4: 0 | AN4: 0 | AO4: 0 | AP4: 0 | AQ4: 0 | AR4: 0 | AS4: 0 | AT4: 0 | AU4: 0 | AV4: 0 | AW4: 0 | AX4: 0 | AY4: 0 | AZ4: 0 | BA4: 0 | BB4: 0 | BC4: 0 | BD4: 0 | BE4: 0 | BF4: 0 | BG4: 0 | BH4: 0 | BI4: 0 | BJ4: 0 | BK4: 0 | BL4: 0 | BM4: 0 | BN4: 0 | BO4: 0 | BP4: 0 | BQ4: 0 | BR4: 0 | BS4: 0 | BT4: 0 | BU4: 0 | BV4: 0 | BW4: 0 | BX4: 0 | BY4: 0 | BZ4: 0 | CA4: 0 | CB4: 0 | CC4: 0 | CD4: 0 | CE4: 0 | CF4: 0 | CG4: 0 | CH4: 0 | CI4: 0 | CJ4: 0 | CK4: 0 | CL4: 0 | CM4: 0 | CN4: 0 | CO4: 0 | CP4: 0 | CQ4: 0 | CR4: 0 | CS4: 0 | CT4: 0 | CU4: 0 | CV4: 0 | CW4: 0
A5: 0.017 | B5: 0 | C5: 0 | D5: 0 | E5: 0 | F5: 0 | G5: 0 | H5: 0 | I5: 0 | J5: 0 | K5: 0 | L5: 0 | M5: 0 | N5: 0 | O5: 0 | P5: 0 | Q5: 0 | R5: 0 | S5: 0 | T5: 0 | U5: 0 | V5: 0 | W5: 0 | X5: 0 | Y5: 0 | Z5: 0 | AA5: 0 | AB5: 0 | AC5: 0 | AD5: 0 | AE5: 0 | AF5: 0 | AG5: 0 | AH5: 0 | AI5: 0 | AJ5: 0 | AK5: 0 | AL5: 0 | AM5: 0 | AN5: 0 | AO5: 0 | AP5: 0 | AQ5: 0 | AR5: 0 | AS5: 0 | AT5: 0 | AU5: 0 | AV5: 0 | AW5: 0 | AX5: 0 | AY5: 0 | AZ5: 0 | BA5: 0 | BB5: 0 | BC5: 0 | BD5: 0 | BE5: 0 | BF5: 0 | BG5: 0 | BH5: 0 | BI5: 0 | BJ5: 0 | BK5: 0 | BL5: 0 | BM5: 0 | BN5: 0 | BO5: 0 | BP5: 0 | BQ5: 0 | BR5: 0 | BS5: 0 | BT5: 0 | BU5: 0 | BV5: 0 | BW5: 0 | BX5: 0 | BY5: 0 | BZ5: 0 | CA5: 0 | CB5: 0 | CC5: 0 | CD5: 0 | CE5: 0 | CF5: 0 | CG5: 0 | CH5: 0 | CI5: 0 | CJ5: 0 | CK5: 0 | CL5: 0 | CM5: 0 | CN5: 0 | CO5: 0 | CP5: 0 | CQ5: 0 | CR5: 0 | CS5: 0 | CT5: 0 | CU5: 0 | CV5: 0 | CW5: 0
A6: 0.02 | B6: 0 | C6: 0 | D6: 0 | E6: 0 | F6: 0 | G6: 0 | H6: 0 | I6: 0 | J6: 0 | K6: 0 | L6: 0 | M6: 0 | N6: 0 | O6: 0 | P6: 0 | Q6: 0 | R6: 0 | S6: 0 | T6: 0 | U6: 0 | V6: 0 | W6: 0 | X6: 0 | Y6: 0 | Z6: 0 | AA6: 0 | AB6: 0 | AC6: 0 | AD6: 0 | AE6: 0 | AF6: 0 | AG6: 0 | AH6: 0 | AI6: 0 | AJ6: 0 | AK6: 0 | AL6: 0 | AM6: 0 | AN6: 0 | AO6: 0 | AP6: 0 | AQ6: 0 | AR6: 0 | AS6: 0 | AT6: 0 | AU6: 0 | AV6: 0 | AW6: 0 | AX6: 0 | AY6: 0 | AZ6: 0 | BA6: 0 | BB6: 0 | BC6: 0 | BD6: 0 | BE6: 0 | BF6: 0 | BG6: 0 | BH6: 0 | BI6: 0 | BJ6: 0 | BK6: 0 | BL6: 0 | BM6: 0 | BN6: 0 | BO6: 0 | BP6: 0 | BQ6: 0 | BR6: 0 | BS6: 0 | BT6: 0 | BU6: 0 | BV6: 0 | BW6: 0 | BX6: 0 | BY6: 0 | BZ6: 0 | CA6: 0 | CB6: 0 | CC6: 0 | CD6: 0 | CE6: 0 | CF6: 0 | CG6: 0 | CH6: 0 | CI6: 0 | CJ6: 0 | CK6: 0 | CL6: 0 | CM6: 0 | CN6: 0 | CO6: 0 | CP6: 0 | CQ6: 0 | CR6: 0 | CS6: 0 | CT6: 0 | CU6: 0 | CV6: 0 | CW6: 0
A7: 0.023 | B7: 0 | C7: 0 | D7: 0 | E7: 0 | F7: 0 | G7: 0 | H7: 0 | I7: 0 | J7: 0 | K7: 0 | L7: 0 | M7: 0 | N7: 0 | O7: 0 | P7: 0 | Q7: 0 | R7: 0 | S7: 0 | T7: 0 | U7: 0 | V7: 0 | W7: 0 | X7: 0 | Y7: 0 | Z7: 0 | AA7: 0 | AB7: 0 | AC7: 0 | AD7: 0 | AE7: 0 | AF7: 0 | AG7: 0 | AH7: 0 | AI7: 0 | AJ7: 0 | AK7: 0 | AL7: 0 | AM7: 0 | AN7: 0 | AO7: 0 | AP7: 0 | AQ7: 0 | AR7: 0 | AS7: 0 | AT7: 0 | AU7: 0 | AV7: 0 | AW7: 0 | AX7: 0 | AY7: 0 | AZ7: 0 | BA7: 0 | BB7: 0 | BC7: 0 | BD7: 0 | BE7: 0 | BF7: 0 | BG7: 0 | BH7: 0 | BI7: 0 | BJ7: 0 | BK7: 0 | BL7: 0 | BM7: 0 | BN7: 0 | BO7: 0 | BP7: 0 | BQ7: 0 | BR7: 0 | BS7: 0 | BT7: 0 | BU7: 0 | BV7: 0 | BW7: 0 | BX7: 0 | BY7: 0 | BZ7: 0 | CA7: 0 | CB7: 0 | CC7: 0 | CD7: 0 | CE7: 0 | CF7: 0 | CG7: 0 | CH7: 0 | CI7: 0 | CJ7: 0 | CK7: 0 | CL7: 0 | CM7: 0 | CN7: 0 | CO7: 0 | CP7: 0 | CQ7: 0 | CR7: 0 | CS7: 0 | CT7: 0 | CU7: 0 | CV7: 0 | CW7: 0
A8: 0.026 | B8: 0 | C8: 0 | D8: 0 | E8: 0 | F8: 0 | G8: 0 | H8: 0 | I8: 0 | J8: 0 | K8: 0 | L8: 0 | M8: 0 | N8: 0 | O8: 0 | P8: 0 | Q8: 0 | R8: 0 | S8: 0 | T8: 0 | U8: 0 | V8: 0 | W8: 0 | X8: 0 | Y8: 0 | Z8: 0 | AA8: 0 | AB8: 0 | AC8: 0 | AD8: 0 | AE8: 0 | AF8: 0 | AG8: 0 | AH8: 0 | AI8: 0 | AJ8: 0 | AK8: 0 | AL8: 0 | AM8: 0 | AN8: 0 | AO8: 0 | AP8: 0 | AQ8: 0 | AR8: 0 | AS8: 0 | AT8: 0 | AU8: 0 | AV8: 0 | AW8: 0 | AX8: 0 | AY8: 0 | AZ8: 0 | BA8: 0 | BB8: 0 | BC8: 0 | BD8: 0 | BE8: 0 | BF8: 0 | BG8: 0 | BH8: 0 | BI8: 0 | BJ8: 0 | BK8: 0 | BL8: 0 | BM8: 0 | BN8: 0 | BO8: 0 | BP8: 0 | BQ8: 0 | BR8: 0 | BS8: 0 | BT8: 0 | BU8: 0 | BV8: 0 | BW8: 0 | BX8: 0 | BY8: 0 | BZ8: 0 | CA8: 0 | CB8: 0 | CC8: 0 | CD8: 0 | CE8: 0 | CF8: 0 | CG8: 0 | CH8: 0 | CI8: 0 | CJ8: 0 | CK8: 0 | CL8: 0 | CM8: 0 | CN8: 0 | CO8: 0 | CP8: 0 | CQ8: 0 | CR8: 0 | CS8: 0 | CT8: 0 | CU8: 0 | CV8: 0 | CW8: 0
A9: 0.03 | B9: 0 | C9: 0 | D9: 0 | E9: 0 | F9: 0 | G9: 0 | H9: 0 | I9: 0 | J9: 0 | K9: 0 | L9: 0 | M9: 0 | N9: 0 | O9: 0 | P9: 0 | Q9: 0 | R9: 0 | S9: 0 | T9: 0 | U9: 0 | V9: 0 | W9: 0 | X9: 0 | Y9: 0 | Z9: 0 | AA9: 0 | AB9: 0 | AC9: 0 | AD9: 0 | AE9: 0 | AF9: 0 | AG9: 0 | AH9: 0 | AI9: 0 | AJ9: 0 | AK9: 0 | AL9: 0 | AM9: 0 | AN9: 0 | AO9: 0 | AP9: 0 | AQ9: 0 | AR9: 0 | AS9: 0 | AT9: 0 | AU9: 0 | AV9: 0 | AW9: 0 | AX9: 0 | AY9: 0 | AZ9: 0 | BA9: 0 | BB9: 0 | BC9: 0 | BD9: 0 | BE9: 0 | BF9: 0 | BG9: 0 | BH9: 0 | BI9: 0 | BJ9: 0 | BK9: 0 | BL9: 0 | BM9: 0 | BN9: 0 | BO9: 0 | BP9: 0 | BQ9: 0 | BR9: 0 | BS9: 0 | BT9: 0 | BU9: 0 | BV9: 0 | BW9: 0 | BX9: 0 | BY9: 0 | BZ9: 0 | CA9: 0 | CB9: 0 | CC9: 0 | CD9: 0 | CE9: 0 | CF9: 0 | CG9: 0 | CH9: 0 | CI9: 0 | CJ9: 0 | CK9: 0 | CL9: 0 | CM9: 0 | CN9: 0 | CO9: 0 | CP9: 0 | CQ9: 0 | CR9: 0 | CS9: 0 | CT9: 0 | CU9: 0 | CV9: 0 | CW9: 0
A10: 0.034 | B10: 0 | C10: 0 | D10: 0 | E10: 0 | F10: 0 | G10: 0 | H10: 0 | I10: 0 | J10: 0 | K10: 0 | L10: 0 | M10: 0 | N10: 0 | O10: 0 | P10: 0 | Q10: 0 | R10: 0 | S10: 0 | T10: 0 | U10: 0 | V10: 0 | W10: 0 | X10: 0 | Y10: 0 | Z10: 0 | AA10: 0 | AB10: 0 | AC10: 0 | AD10: 0 | AE10: 0 | AF10: 0 | AG10: 0 | AH10: 0 | AI10: 0 | AJ10: 0 | AK10: 0 | AL10: 0 | AM10: 0 | AN10: 0 | AO10: 0 | AP10: 0 | AQ10: 0 | AR10: 0 | AS10: 0 | AT10: 0 | AU10: 0 | AV10: 0 | AW10: 0 | AX10: 0 | AY10: 0 | AZ10: 0 | BA10: 0 | BB10: 0 | BC10: 0 | BD10: 0 | BE10: 0 | BF10: 0 | BG10: 0 | BH10: 0 | BI10: 0 | BJ10: 0 | BK10: 0 | BL10: 0 | BM10: 0 | BN10: 0 | BO10: 0 | BP10: 0 | BQ10: 0 | BR10: 0 | BS10: 0 | BT10: 0 | BU10: 0 | BV10: 0 | BW10: 0 | BX10: 0 | BY10: 0 | BZ10: 0 | CA10: 0 | CB10: 0 | CC10: 0 | CD10: 0 | CE10: 0 | CF10: 0 | CG10: 0 | CH10: 0 | CI10: 0 | CJ10: 0 | CK10: 0 | CL10: 0 | CM10: 0 | CN10: 0 | CO10: 0 | CP10: 0 | CQ10: 0 | CR10: 0 | CS10: 0 | CT10: 0 | CU10: 0 | CV10: 0 | CW10: 0
A11: 0.039 | B11: 0 | C11: 0 | D11: 0 | E11: 0 | F11: 0 | G11: 0 | H11: 0 | I11: 0 | J11: 0 | K11: 0 | L11: 0 | M11: 0 | N11: 0 | O11: 0 | P11: 0 | Q11: 0 | R11: 0 | S11: 0 | T11: 0 | U11: 0 | V11: 0 | W11: 0 | X11: 0 | Y11: 0 | Z11: 0 | AA11: 0 | AB11: 0 | AC11: 0 | AD11: 0 | AE11: 0 | AF11: 0 | AG11: 0 | AH11: 0 | AI11: 0 | AJ11: 0 | AK11: 0 | AL11: 0 | AM11: 0 | AN11: 0 | AO11: 0 | AP11: 0 | AQ11: 0 | AR11: 0 | AS11: 0 | AT11: 0 | AU11: 0 | AV11: 0 | AW11: 0 | AX11: 0 | AY11: 0 | AZ11: 0 | BA11: 0 | BB11: 0 | BC11: 0 | BD11: 0 | BE11: 0 | BF11: 0 | BG11: 0 | BH11: 0 | BI11: 0 | BJ11: 0 | BK11: 0 | BL11: 0 | BM11: 0 | BN11: 0 | BO11: 0 | BP11: 0 | BQ11: 0 | BR11: 0 | BS11: 0 | BT11: 0 | BU11: 0 | BV11: 0 | BW11: 0 | BX11: 0 | BY11: 0 | BZ11: 0 | CA11: 0 | CB11: 0 | CC11: 0 | CD11: 0 | CE11: 0 | CF11: 0 | CG11: 0 | CH11: 0 | CI11: 0 | CJ11: 0 | CK11: 0 | CL11: 0 | CM11: 0 | CN11: 0 | CO11: 0 | CP11: 0 | CQ11: 0 | CR11: 0 | CS11: 0 | CT11: 0 | CU11: 0 | CV11: 0 | CW11: 0
A12: 0.044 | B12: 0 | C12: 0 | D12: 0 | E12: 0 | F12: 0 | G12: 0 | H12: 0 | I12: 0 | J12: 0 | K12: 0 | L12: 0 | M12: 0 | N12: 0 | O12: 0 | P12: 0 | Q12: 0 | R12: 0 | S12: 0 | T12: 0 | U12: 0 | V12: 0 | W12: 0 | X12: 0 | Y12: 0 | Z12: 0 | AA12: 0 | AB12: 0 | AC12: 0 | AD12: 0 | AE12: 0 | AF12: 0 | AG12: 0 | AH12: 0 | AI12: 0 | AJ12: 0 | AK12: 0 | AL12: 0 | AM12: 0 | AN12: 0 | AO12: 0 | AP12: 0 | AQ12: 0 | AR12: 0 | AS12: 0 | AT12: 0 | AU12: 0 | AV12: 0 | AW12: 0 | AX12: 0 | AY12: 0 | AZ12: 0 | BA12: 0 | BB12: 0 | BC12: 0 | BD12: 0 | BE12: 0 | BF12: 0 | BG12: 0 | BH12: 0 | BI12: 0 | BJ12: 0 | BK12: 0 | BL12: 0 | BM12: 0 | BN12: 0 | BO12: 0 | BP12: 0 | BQ12: 0 | BR12: 0 | BS12: 0 | BT12: 0 | BU12: 0 | BV12: 0 | BW12: 0 | BX12: 0 | BY12: 0 | BZ12: 0 | CA12: 0 | CB12: 0 | CC12: 0 | CD12: 0 | CE12: 0 | CF12: 0 | CG12: 0 | CH12: 0 | CI12: 0 | CJ12: 0 | CK12: 0 | CL12: 0 | CM12: 0 | CN12: 0 | CO12: 0 | CP12: 0 | CQ12: 0 | CR12: 0 | CS12: 0 | CT12: 0 | CU12: 0 | CV12: 0 | CW12: 0
A13: 0.051 | B13: 0 | C13: 0 | D13: 0 | E13: 0 | F13: 0 | G13: 0 | H13: 0 | I13: 0 | J13: 0 | K13: 0 | L13: 0 | M13: 0 | N13: 0 | O13: 0 | P13: 0 | Q13: 0 | R13: 0 | S13: 0 | T13: 0 | U13: 0 | V13: 0 | W13: 0 | X13: 0 | Y13: 0 | Z13: 0 | AA13: 0 | AB13: 0 | AC13: 0 | AD13: 0 | AE13: 0 | AF13: 0 | AG13: 0 | AH13: 0 | AI13: 0 | AJ13: 0 | AK13: 0 | AL13: 0 | AM13: 0 | AN13: 0 | AO13: 0 | AP13: 0 | AQ13: 0 | AR13: 0 | AS13: 0 | AT13: 0 | AU13: 0 | AV13: 0 | AW13: 0 | AX13: 0 | AY13: 0 | AZ13: 0 | BA13: 0 | BB13: 0 | BC13: 0 | BD13: 0 | BE13: 0 | BF13: 0 | BG13: 0 | BH13: 0 | BI13: 0 | BJ13: 0 | BK13: 0 | BL13: 0 | BM13: 0 | BN13: 0 | BO13: 0 | BP13: 0 | BQ13: 0 | BR13: 0 | BS13: 0 | BT13: 0 | BU13: 0 | BV13: 0 | BW13: 0 | BX13: 0 | BY13: 0 | BZ13: 0 | CA13: 0 | CB13: 0 | CC13: 0 | CD13: 0 | CE13: 0 | CF13: 0 | CG13: 0 | CH13: 0 | CI13: 0 | CJ13: 0 | CK13: 0 | CL13: 0 | CM13: 0 | CN13: 0 | CO13: 0 | CP13: 0 | CQ13: 0 | CR13: 0 | CS13: 0 | CT13: 0 | CU13: 0 | CV13: 0 | CW13: 0
... A94: 3000 | B94: 0 | C94: 0 | D94: 0 | E94: 0 | F94: 0 | G94: 0 | H94: 0 | I94: 0 | J94: 0 | K94: 0 | L94: 0 | M94: 0 | N94: 0 | O94: 0 | P94: 0 | Q94: 0 | R94: 0 | S94: 0 | T94: 0 | U94: 0 | V94: 0 | W94: 0 | X94: 0 | Y94: 0 | Z94: 0 | AA94: 0 | AB94: 0 | AC94: 0 | AD94: 0 | AE94: 0 | AF94: 0 | AG94: 0 | AH94: 0 | AI94: 0 | AJ94: 0 | AK94: 0 | AL94: 0 | AM94: 0 | AN94: 0 | AO94: 0 | AP94: 0 | AQ94: 0 | AR94: 0 | AS94: 0 | AT94: 0 | AU94: 0 | AV94: 0 | AW94: 0 | AX94: 0 | AY94: 0 | AZ94: 0 | BA94: 0 | BB94: 0 | BC94: 0 | BD94: 0 | BE94: 0 | BF94: 0 | BG94: 0 | BH94: 0 | BI94: 0 | BJ94: 0 | BK94: 0 | BL94: 0 | BM94: 0 | BN94: 0 | BO94: 0 | BP94: 0 | BQ94: 0 | BR94: 0 | BS94: 0 | BT94: 0 | BU94: 0 | BV94: 0 | BW94: 0 | BX94: 0 | BY94: 0 | BZ94: 0 | CA94: 0 | CB94: 0 | CC94: 0 | CD94: 0 | CE94: 0 | CF94: 0 | CG94: 0 | CH94: 0 | CI94: 0 | CJ94: 0 | CK94: 0 | CL94: 0 | CM94: 0 | CN94: 0 | CO94: 0 | CP94: 0 | CQ94: 0 | CR94: 0 | CS94: 0 | CT94: 0 | CU94: 0 | CV94: 0 | CW94: 0
B95: =SUM(B2:B94) -> 100.001 | C95: =SUM(C2:C94) -> 100 | D95: =SUM(D2:D94) -> 100.001 | E95: =SUM(E2:E94) -> 100.003 | F95: =SUM(F2:F94) -> 100.002 | G95: =SUM(G2:G94) -> 100.003 | H95: =SUM(H2:H94) -> 100.005 | I95: =SUM(I2:I94) -> 100.002 | ... CW95: =SUM(CW2:CW94) -> 99.999

Sheet Laser Crop
A1: dia (um) | B1: fu-19 | C1: fu-01 | D1: fu-20 | E1: fu-16 | F1: fu-13 | G1: fu-14 | H1: fu-10 | I1: fu-11 | J1: fu-03 | K1: bint-11 | L1: bint-09 | M1: bint-12 | N1: bint-03 | O1: bint-05 | P1: baie-19 | Q1: baie-18 | R1: baie-16 | S1: baie-20 | T1: baie-10 | U1: baie-09 | V1: baie-11 | W1: baie-06 | X1: baie-08 | Y1: baie-04 | Z1: baie-01 | AA1: baie-05 | AB1: baie-02 | AC1: baie-15 | AD1: ce-46 | AE1: ce-47 | AF1: binf-08 | AG1: binf-01 | AH1: ce-50 | AI1: ce-48 | AJ1: binf-18 | AK1: binf-13 | AL1: ce-45 | AM1: binf-17 | AN1: ce-43 | AO1: ce-44 | AP1: ce-40 | AQ1: ce-42 | AR1: ce-37 | AS1: ce-39 | AT1: ce-34 | AU1: ce-36 | AV1: ce-32 | AW1: ce-33 | AX1: ce-30 | AY1: ce-31 | AZ1: ce-27 | BA1: ce-28 | BB1: ce-23 | BC1: ce-25 | BD1: ce-20 | BE1: ce-21 | BF1: ce-15 | BG1: ce-19 | BH1: ce-13 | BI1: ce-08 | BJ1: ce-14 | BK1: ce-06 | BL1: ce-09 | BM1: ce-04 | BN1: ce-07 | BO1: ce-05 | BP1: ce-01 | BQ1: ce-02 | BR1: binf-02 | BS1: ce-51 | BT1: binf-10 | BU1: ce-24 | BV1: binf-15 | BW1: ce-03 | BX1: fu-15 | BY1: ce-12 | BZ1: fu-12 | CA1: ce-16 | CB1: bint-14 | CC1: fu-05 | CD1: binf-04 | CE1: fu-18 | CF1: binf-20 | CG1: binf-05 | CH1: ce-08.2 | CI1: baie-15.2 | CJ1: bint-08 | CK1: fu-19.2 | CL1: fu-02 | CM1: fu-04 | CN1: ce-37.2 | CO1: ce-18 | CP1: ce-10 | CQ1: ce-22 | CR1: bint-15 | CS1: bint-02 | CT1: bint-06 | CU1: binf-18.2 | CV1: binf-07 | CW1: binf-12
A2: 0.011 | B2: =(Laser!B2/SUM(Laser!B$2:B$80))*100 -> 0 | C2: =(Laser!C2/SUM(Laser!C$2:C$80))*100 -> 0 | D2: =(Laser!D2/SUM(Laser!D$2:D$80))*100 -> 0 | E2: =(Laser!E2/SUM(Laser!E$2:E$80))*100 -> 0 | F2: =(Laser!F2/SUM(Laser!F$2:F$80))*100 -> 0 | G2: =(Laser!G2/SUM(Laser!G$2:G$80))*100 -> 0 | H2: =(Laser!H2/SUM(Laser!H$2:H$80))*100 -> 0 | I2: =(Laser!I2/SUM(Laser!I$2:I$80))*100 -> 0 | ... CW2: =(Laser!CW2/SUM(Laser!CW$2:CW$80))*100 -> 0
A3: 0.013 | B3: =(Laser!B3/SUM(Laser!B$2:B$80))*100 -> 0 | C3: =(Laser!C3/SUM(Laser!C$2:C$80))*100 -> 0 | D3: =(Laser!D3/SUM(Laser!D$2:D$80))*100 -> 0 | E3: =(Laser!E3/SUM(Laser!E$2:E$80))*100 -> 0 | F3: =(Laser!F3/SUM(Laser!F$2:F$80))*100 -> 0 | G3: =(Laser!G3/SUM(Laser!G$2:G$80))*100 -> 0 | H3: =(Laser!H3/SUM(Laser!H$2:H$80))*100 -> 0 | I3: =(Laser!I3/SUM(Laser!I$2:I$80))*100 -> 0 | ... CW3: =(Laser!CW3/SUM(Laser!CW$2:CW$80))*100 -> 0
A4: 0.015 | B4: =(Laser!B4/SUM(Laser!B$2:B$80))*100 -> 0 | C4: =(Laser!C4/SUM(Laser!C$2:C$80))*100 -> 0 | D4: =(Laser!D4/SUM(Laser!D$2:D$80))*100 -> 0 | E4: =(Laser!E4/SUM(Laser!E$2:E$80))*100 -> 0 | F4: =(Laser!F4/SUM(Laser!F$2:F$80))*100 -> 0 | G4: =(Laser!G4/SUM(Laser!G$2:G$80))*100 -> 0 | H4: =(Laser!H4/SUM(Laser!H$2:H$80))*100 -> 0 | I4: =(Laser!I4/SUM(Laser!I$2:I$80))*100 -> 0 | ... CW4: =(Laser!CW4/SUM(Laser!CW$2:CW$80))*100 -> 0
A5: 0.017 | B5: =(Laser!B5/SUM(Laser!B$2:B$80))*100 -> 0 | C5: =(Laser!C5/SUM(Laser!C$2:C$80))*100 -> 0 | D5: =(Laser!D5/SUM(Laser!D$2:D$80))*100 -> 0 | E5: =(Laser!E5/SUM(Laser!E$2:E$80))*100 -> 0 | F5: =(Laser!F5/SUM(Laser!F$2:F$80))*100 -> 0 | G5: =(Laser!G5/SUM(Laser!G$2:G$80))*100 -> 0 | H5: =(Laser!H5/SUM(Laser!H$2:H$80))*100 -> 0 | I5: =(Laser!I5/SUM(Laser!I$2:I$80))*100 -> 0 | ... CW5: =(Laser!CW5/SUM(Laser!CW$2:CW$80))*100 -> 0
A6: 0.02 | B6: =(Laser!B6/SUM(Laser!B$2:B$80))*100 -> 0 | C6: =(Laser!C6/SUM(Laser!C$2:C$80))*100 -> 0 | D6: =(Laser!D6/SUM(Laser!D$2:D$80))*100 -> 0 | E6: =(Laser!E6/SUM(Laser!E$2:E$80))*100 -> 0 | F6: =(Laser!F6/SUM(Laser!F$2:F$80))*100 -> 0 | G6: =(Laser!G6/SUM(Laser!G$2:G$80))*100 -> 0 | H6: =(Laser!H6/SUM(Laser!H$2:H$80))*100 -> 0 | I6: =(Laser!I6/SUM(Laser!I$2:I$80))*100 -> 0 | ... CW6: =(Laser!CW6/SUM(Laser!CW$2:CW$80))*100 -> 0
A7: 0.023 | B7: =(Laser!B7/SUM(Laser!B$2:B$80))*100 -> 0 | C7: =(Laser!C7/SUM(Laser!C$2:C$80))*100 -> 0 | D7: =(Laser!D7/SUM(Laser!D$2:D$80))*100 -> 0 | E7: =(Laser!E7/SUM(Laser!E$2:E$80))*100 -> 0 | F7: =(Laser!F7/SUM(Laser!F$2:F$80))*100 -> 0 | G7: =(Laser!G7/SUM(Laser!G$2:G$80))*100 -> 0 | H7: =(Laser!H7/SUM(Laser!H$2:H$80))*100 -> 0 | I7: =(Laser!I7/SUM(Laser!I$2:I$80))*100 -> 0 | ... CW7: =(Laser!CW7/SUM(Laser!CW$2:CW$80))*100 -> 0
A8: 0.026 | B8: =(Laser!B8/SUM(Laser!B$2:B$80))*100 -> 0 | C8: =(Laser!C8/SUM(Laser!C$2:C$80))*100 -> 0 | D8: =(Laser!D8/SUM(Laser!D$2:D$80))*100 -> 0 | E8: =(Laser!E8/SUM(Laser!E$2:E$80))*100 -> 0 | F8: =(Laser!F8/SUM(Laser!F$2:F$80))*100 -> 0 | G8: =(Laser!G8/SUM(Laser!G$2:G$80))*100 -> 0 | H8: =(Laser!H8/SUM(Laser!H$2:H$80))*100 -> 0 | I8: =(Laser!I8/SUM(Laser!I$2:I$80))*100 -> 0 | ... CW8: =(Laser!CW8/SUM(Laser!CW$2:CW$80))*100 -> 0
A9: 0.03 | B9: =(Laser!B9/SUM(Laser!B$2:B$80))*100 -> 0 | C9: =(Laser!C9/SUM(Laser!C$2:C$80))*100 -> 0 | D9: =(Laser!D9/SUM(Laser!D$2:D$80))*100 -> 0 | E9: =(Laser!E9/SUM(Laser!E$2:E$80))*100 -> 0 | F9: =(Laser!F9/SUM(Laser!F$2:F$80))*100 -> 0 | G9: =(Laser!G9/SUM(Laser!G$2:G$80))*100 -> 0 | H9: =(Laser!H9/SUM(Laser!H$2:H$80))*100 -> 0 | I9: =(Laser!I9/SUM(Laser!I$2:I$80))*100 -> 0 | ... CW9: =(Laser!CW9/SUM(Laser!CW$2:CW$80))*100 -> 0
A10: 0.034 | B10: =(Laser!B10/SUM(Laser!B$2:B$80))*100 -> 0 | C10: =(Laser!C10/SUM(Laser!C$2:C$80))*100 -> 0 | D10: =(Laser!D10/SUM(Laser!D$2:D$80))*100 -> 0 | E10: =(Laser!E10/SUM(Laser!E$2:E$80))*100 -> 0 | F10: =(Laser!F10/SUM(Laser!F$2:F$80))*100 -> 0 | G10: =(Laser!G10/SUM(Laser!G$2:G$80))*100 -> 0 | H10: =(Laser!H10/SUM(Laser!H$2:H$80))*100 -> 0 | I10: =(Laser!I10/SUM(Laser!I$2:I$80))*100 -> 0 | ... CW10: =(Laser!CW10/SUM(Laser!CW$2:CW$80))*100 -> 0
A11: 0.039 | B11: =(Laser!B11/SUM(Laser!B$2:B$80))*100 -> 0 | C11: =(Laser!C11/SUM(Laser!C$2:C$80))*100 -> 0 | D11: =(Laser!D11/SUM(Laser!D$2:D$80))*100 -> 0 | E11: =(Laser!E11/SUM(Laser!E$2:E$80))*100 -> 0 | F11: =(Laser!F11/SUM(Laser!F$2:F$80))*100 -> 0 | G11: =(Laser!G11/SUM(Laser!G$2:G$80))*100 -> 0 | H11: =(Laser!H11/SUM(Laser!H$2:H$80))*100 -> 0 | I11: =(Laser!I11/SUM(Laser!I$2:I$80))*100 -> 0 | ... CW11: =(Laser!CW11/SUM(Laser!CW$2:CW$80))*100 -> 0
A12: 0.044 | B12: =(Laser!B12/SUM(Laser!B$2:B$80))*100 -> 0 | C12: =(Laser!C12/SUM(Laser!C$2:C$80))*100 -> 0 | D12: =(Laser!D12/SUM(Laser!D$2:D$80))*100 -> 0 | E12: =(Laser!E12/SUM(Laser!E$2:E$80))*100 -> 0 | F12: =(Laser!F12/SUM(Laser!F$2:F$80))*100 -> 0 | G12: =(Laser!G12/SUM(Laser!G$2:G$80))*100 -> 0 | H12: =(Laser!H12/SUM(Laser!H$2:H$80))*100 -> 0 | I12: =(Laser!I12/SUM(Laser!I$2:I$80))*100 -> 0 | ... CW12: =(Laser!CW12/SUM(Laser!CW$2:CW$80))*100 -> 0
A13: 0.051 | B13: =(Laser!B13/SUM(Laser!B$2:B$80))*100 -> 0 | C13: =(Laser!C13/SUM(Laser!C$2:C$80))*100 -> 0 | D13: =(Laser!D13/SUM(Laser!D$2:D$80))*100 -> 0 | E13: =(Laser!E13/SUM(Laser!E$2:E$80))*100 -> 0 | F13: =(Laser!F13/SUM(Laser!F$2:F$80))*100 -> 0 | G13: =(Laser!G13/SUM(Laser!G$2:G$80))*100 -> 0 | H13: =(Laser!H13/SUM(Laser!H$2:H$80))*100 -> 0 | I13: =(Laser!I13/SUM(Laser!I$2:I$80))*100 -> 0 | ... CW13: =(Laser!CW13/SUM(Laser!CW$2:CW$80))*100 -> 0
... A80: 451.556 | B80: =(Laser!B80/SUM(Laser!B$2:B$80))*100 -> 0 | C80: =(Laser!C80/SUM(Laser!C$2:C$80))*100 -> 0.68459461 | D80: =(Laser!D80/SUM(Laser!D$2:D$80))*100 -> 21.710573 | E80: =(Laser!E80/SUM(Laser!E$2:E$80))*100 -> 0.31799046 | F80: =(Laser!F80/SUM(Laser!F$2:F$80))*100 -> 0 | G80: =(Laser!G80/SUM(Laser!G$2:G$80))*100 -> 0 | H80: =(Laser!H80/SUM(Laser!H$2:H$80))*100 -> 0 | I80: =(Laser!I80/SUM(Laser!I$2:I$80))*100 -> 0 | ... CW80: =(Laser!CW80/SUM(Laser!CW$2:CW$80))*100 -> 2.222998

Sheet Laser Perc Mass
A1: dia (um) | B1: fu-19 | C1: fu-01 | D1: fu-20 | E1: fu-16 | F1: fu-13 | G1: fu-14 | H1: fu-10 | I1: fu-11 | J1: fu-03 | K1: bint-11 | L1: bint-09 | M1: bint-12 | N1: bint-03 | O1: bint-05 | P1: baie-19 | Q1: baie-18 | R1: baie-16 | S1: baie-20 | T1: baie-10 | U1: baie-09 | V1: baie-11 | W1: baie-06 | X1: baie-08 | Y1: baie-04 | Z1: baie-01 | AA1: baie-05 | AB1: baie-02 | AC1: baie-15 | AD1: ce-46 | AE1: ce-47 | AF1: binf-08 | AG1: binf-01 | AH1: ce-50 | AI1: ce-48 | AJ1: binf-18 | AK1: binf-13 | AL1: ce-45 | AM1: binf-17 | AN1: ce-43 | AO1: ce-44 | AP1: ce-40 | AQ1: ce-42 | AR1: ce-37 | AS1: ce-39 | AT1: ce-34 | AU1: ce-36 | AV1: ce-32 | AW1: ce-33 | AX1: ce-30 | AY1: ce-31 | AZ1: ce-27 | BA1: ce-28 | BB1: ce-23 | BC1: ce-25 | BD1: ce-20 | BE1: ce-21 | BF1: ce-15 | BG1: ce-19 | BH1: ce-13 | BI1: ce-08 | BJ1: ce-14 | BK1: ce-06 | BL1: ce-09 | BM1: ce-04 | BN1: ce-07 | BO1: ce-05 | BP1: ce-01 | BQ1: ce-02 | BR1: binf-02 | BS1: ce-51 | BT1: binf-10 | BU1: ce-24 | BV1: binf-15 | BW1: ce-03 | BX1: fu-15 | BY1: ce-12 | BZ1: fu-12 | CA1: ce-16 | CB1: bint-14 | CC1: fu-05 | CD1: binf-04 | CE1: fu-18 | CF1: binf-20 | CG1: binf-05 | CH1: ce-08.2 | CI1: baie-15.2 | CJ1: bint-08 | CK1: fu-19.2 | CL1: fu-02 | CM1: fu-04 | CN1: ce-37.2 | CO1: ce-18 | CP1: ce-10 | CQ1: ce-22 | CR1: bint-15 | CS1: bint-02 | CT1: bint-06 | CU1: binf-18.2 | CV1: binf-07 | CW1: binf-12
A2: 0.011 | B2: =(Laser!B2/SUM(Laser!B$2:B$80)) -> 0 | C2: =(Laser!C2/SUM(Laser!C$2:C$80)) -> 0 | D2: =(Laser!D2/SUM(Laser!D$2:D$80)) -> 0 | E2: =(Laser!E2/SUM(Laser!E$2:E$80)) -> 0 | F2: =(Laser!F2/SUM(Laser!F$2:F$80)) -> 0 | G2: =(Laser!G2/SUM(Laser!G$2:G$80)) -> 0 | H2: =(Laser!H2/SUM(Laser!H$2:H$80)) -> 0 | I2: =(Laser!I2/SUM(Laser!I$2:I$80)) -> 0 | ... CW2: =(Laser!CW2/SUM(Laser!CW$2:CW$80)) -> 0
A3: 0.013 | B3: =(Laser!B3/SUM(Laser!B$2:B$80)) -> 0 | C3: =(Laser!C3/SUM(Laser!C$2:C$80)) -> 0 | D3: =(Laser!D3/SUM(Laser!D$2:D$80)) -> 0 | E3: =(Laser!E3/SUM(Laser!E$2:E$80)) -> 0 | F3: =(Laser!F3/SUM(Laser!F$2:F$80)) -> 0 | G3: =(Laser!G3/SUM(Laser!G$2:G$80)) -> 0 | H3: =(Laser!H3/SUM(Laser!H$2:H$80)) -> 0 | I3: =(Laser!I3/SUM(Laser!I$2:I$80)) -> 0 | ... CW3: =(Laser!CW3/SUM(Laser!CW$2:CW$80)) -> 0
A4: 0.015 | B4: =(Laser!B4/SUM(Laser!B$2:B$80)) -> 0 | C4: =(Laser!C4/SUM(Laser!C$2:C$80)) -> 0 | D4: =(Laser!D4/SUM(Laser!D$2:D$80)) -> 0 | E4: =(Laser!E4/SUM(Laser!E$2:E$80)) -> 0 | F4: =(Laser!F4/SUM(Laser!F$2:F$80)) -> 0 | G4: =(Laser!G4/SUM(Laser!G$2:G$80)) -> 0 | H4: =(Laser!H4/SUM(Laser!H$2:H$80)) -> 0 | I4: =(Laser!I4/SUM(Laser!I$2:I$80)) -> 0 | ... CW4: =(Laser!CW4/SUM(Laser!CW$2:CW$80)) -> 0
A5: 0.017 | B5: =(Laser!B5/SUM(Laser!B$2:B$80)) -> 0 | C5: =(Laser!C5/SUM(Laser!C$2:C$80)) -> 0 | D5: =(Laser!D5/SUM(Laser!D$2:D$80)) -> 0 | E5: =(Laser!E5/SUM(Laser!E$2:E$80)) -> 0 | F5: =(Laser!F5/SUM(Laser!F$2:F$80)) -> 0 | G5: =(Laser!G5/SUM(Laser!G$2:G$80)) -> 0 | H5: =(Laser!H5/SUM(Laser!H$2:H$80)) -> 0 | I5: =(Laser!I5/SUM(Laser!I$2:I$80)) -> 0 | ... CW5: =(Laser!CW5/SUM(Laser!CW$2:CW$80)) -> 0
A6: 0.02 | B6: =(Laser!B6/SUM(Laser!B$2:B$80)) -> 0 | C6: =(Laser!C6/SUM(Laser!C$2:C$80)) -> 0 | D6: =(Laser!D6/SUM(Laser!D$2:D$80)) -> 0 | E6: =(Laser!E6/SUM(Laser!E$2:E$80)) -> 0 | F6: =(Laser!F6/SUM(Laser!F$2:F$80)) -> 0 | G6: =(Laser!G6/SUM(Laser!G$2:G$80)) -> 0 | H6: =(Laser!H6/SUM(Laser!H$2:H$80)) -> 0 | I6: =(Laser!I6/SUM(Laser!I$2:I$80)) -> 0 | ... CW6: =(Laser!CW6/SUM(Laser!CW$2:CW$80)) -> 0
A7: 0.023 | B7: =(Laser!B7/SUM(Laser!B$2:B$80)) -> 0 | C7: =(Laser!C7/SUM(Laser!C$2:C$80)) -> 0 | D7: =(Laser!D7/SUM(Laser!D$2:D$80)) -> 0 | E7: =(Laser!E7/SUM(Laser!E$2:E$80)) -> 0 | F7: =(Laser!F7/SUM(Laser!F$2:F$80)) -> 0 | G7: =(Laser!G7/SUM(Laser!G$2:G$80)) -> 0 | H7: =(Laser!H7/SUM(Laser!H$2:H$80)) -> 0 | I7: =(Laser!I7/SUM(Laser!I$2:I$80)) -> 0 | ... CW7: =(Laser!CW7/SUM(Laser!CW$2:CW$80)) -> 0
A8: 0.026 | B8: =(Laser!B8/SUM(Laser!B$2:B$80)) -> 0 | C8: =(Laser!C8/SUM(Laser!C$2:C$80)) -> 0 | D8: =(Laser!D8/SUM(Laser!D$2:D$80)) -> 0 | E8: =(Laser!E8/SUM(Laser!E$2:E$80)) -> 0 | F8: =(Laser!F8/SUM(Laser!F$2:F$80)) -> 0 | G8: =(Laser!G8/SUM(Laser!G$2:G$80)) -> 0 | H8: =(Laser!H8/SUM(Laser!H$2:H$80)) -> 0 | I8: =(Laser!I8/SUM(Laser!I$2:I$80)) -> 0 | ... CW8: =(Laser!CW8/SUM(Laser!CW$2:CW$80)) -> 0
A9: 0.03 | B9: =(Laser!B9/SUM(Laser!B$2:B$80)) -> 0 | C9: =(Laser!C9/SUM(Laser!C$2:C$80)) -> 0 | D9: =(Laser!D9/SUM(Laser!D$2:D$80)) -> 0 | E9: =(Laser!E9/SUM(Laser!E$2:E$80)) -> 0 | F9: =(Laser!F9/SUM(Laser!F$2:F$80)) -> 0 | G9: =(Laser!G9/SUM(Laser!G$2:G$80)) -> 0 | H9: =(Laser!H9/SUM(Laser!H$2:H$80)) -> 0 | I9: =(Laser!I9/SUM(Laser!I$2:I$80)) -> 0 | ... CW9: =(Laser!CW9/SUM(Laser!CW$2:CW$80)) -> 0
A10: 0.034 | B10: =(Laser!B10/SUM(Laser!B$2:B$80)) -> 0 | C10: =(Laser!C10/SUM(Laser!C$2:C$80)) -> 0 | D10: =(Laser!D10/SUM(Laser!D$2:D$80)) -> 0 | E10: =(Laser!E10/SUM(Laser!E$2:E$80)) -> 0 | F10: =(Laser!F10/SUM(Laser!F$2:F$80)) -> 0 | G10: =(Laser!G10/SUM(Laser!G$2:G$80)) -> 0 | H10: =(Laser!H10/SUM(Laser!H$2:H$80)) -> 0 | I10: =(Laser!I10/SUM(Laser!I$2:I$80)) -> 0 | ... CW10: =(Laser!CW10/SUM(Laser!CW$2:CW$80)) -> 0
A11: 0.039 | B11: =(Laser!B11/SUM(Laser!B$2:B$80)) -> 0 | C11: =(Laser!C11/SUM(Laser!C$2:C$80)) -> 0 | D11: =(Laser!D11/SUM(Laser!D$2:D$80)) -> 0 | E11: =(Laser!E11/SUM(Laser!E$2:E$80)) -> 0 | F11: =(Laser!F11/SUM(Laser!F$2:F$80)) -> 0 | G11: =(Laser!G11/SUM(Laser!G$2:G$80)) -> 0 | H11: =(Laser!H11/SUM(Laser!H$2:H$80)) -> 0 | I11: =(Laser!I11/SUM(Laser!I$2:I$80)) -> 0 | ... CW11: =(Laser!CW11/SUM(Laser!CW$2:CW$80)) -> 0
A12: 0.044 | B12: =(Laser!B12/SUM(Laser!B$2:B$80)) -> 0 | C12: =(Laser!C12/SUM(Laser!C$2:C$80)) -> 0 | D12: =(Laser!D12/SUM(Laser!D$2:D$80)) -> 0 | E12: =(Laser!E12/SUM(Laser!E$2:E$80)) -> 0 | F12: =(Laser!F12/SUM(Laser!F$2:F$80)) -> 0 | G12: =(Laser!G12/SUM(Laser!G$2:G$80)) -> 0 | H12: =(Laser!H12/SUM(Laser!H$2:H$80)) -> 0 | I12: =(Laser!I12/SUM(Laser!I$2:I$80)) -> 0 | ... CW12: =(Laser!CW12/SUM(Laser!CW$2:CW$80)) -> 0
A13: 0.051 | B13: =(Laser!B13/SUM(Laser!B$2:B$80)) -> 0 | C13: =(Laser!C13/SUM(Laser!C$2:C$80)) -> 0 | D13: =(Laser!D13/SUM(Laser!D$2:D$80)) -> 0 | E13: =(Laser!E13/SUM(Laser!E$2:E$80)) -> 0 | F13: =(Laser!F13/SUM(Laser!F$2:F$80)) -> 0 | G13: =(Laser!G13/SUM(Laser!G$2:G$80)) -> 0 | H13: =(Laser!H13/SUM(Laser!H$2:H$80)) -> 0 | I13: =(Laser!I13/SUM(Laser!I$2:I$80)) -> 0 | ... CW13: =(Laser!CW13/SUM(Laser!CW$2:CW$80)) -> 0
... A80: 451.556 | B80: =(Laser!B80/SUM(Laser!B$2:B$80)) -> 0 | C80: =(Laser!C80/SUM(Laser!C$2:C$80)) -> 0.0068459461 | D80: =(Laser!D80/SUM(Laser!D$2:D$80)) -> 0.21710573 | E80: =(Laser!E80/SUM(Laser!E$2:E$80)) -> 0.0031799046 | F80: =(Laser!F80/SUM(Laser!F$2:F$80)) -> 0 | G80: =(Laser!G80/SUM(Laser!G$2:G$80)) -> 0 | H80: =(Laser!H80/SUM(Laser!H$2:H$80)) -> 0 | I80: =(Laser!I80/SUM(Laser!I$2:I$80)) -> 0 | ... CW80: =(Laser!CW80/SUM(Laser!CW$2:CW$80)) -> 0.02222998

Sheet Laser Pre Merged
A1: dia (um) | B1: fu-19 | C1: fu-01 | D1: fu-20 | E1: fu-16 | F1: fu-13 | G1: fu-14 | H1: fu-10 | I1: fu-11 | J1: fu-03 | K1: bint-11 | L1: bint-09 | M1: bint-12 | N1: bint-03 | O1: bint-05 | P1: baie-19 | Q1: baie-18 | R1: baie-16 | S1: baie-20 | T1: baie-10 | U1: baie-09 | V1: baie-11 | W1: baie-06 | X1: baie-08 | Y1: baie-04 | Z1: baie-01 | AA1: baie-05 | AB1: baie-02 | AC1: baie-15 | AD1: ce-46 | AE1: ce-47 | AF1: binf-08 | AG1: binf-01 | AH1: ce-50 | AI1: ce-48 | AJ1: binf-18 | AK1: binf-13 | AL1: ce-45 | AM1: binf-17 | AN1: ce-43 | AO1: ce-44 | AP1: ce-40 | AQ1: ce-42 | AR1: ce-37 | AS1: ce-39 | AT1: ce-34 | AU1: ce-36 | AV1: ce-32 | AW1: ce-33 | AX1: ce-30 | AY1: ce-31 | AZ1: ce-27 | BA1: ce-28 | BB1: ce-23 | BC1: ce-25 | BD1: ce-20 | BE1: ce-21 | BF1: ce-15 | BG1: ce-19 | BH1: ce-13 | BI1: ce-08 | BJ1: ce-14 | BK1: ce-06 | BL1: ce-09 | BM1: ce-04 | BN1: ce-07 | BO1: ce-05 | BP1: ce-01 | BQ1: ce-02 | BR1: binf-02 | BS1: ce-51 | BT1: binf-10 | BU1: ce-24 | BV1: binf-15 | BW1: ce-03 | BX1: fu-15 | BY1: ce-12 | BZ1: fu-12 | CA1: ce-16 | CB1: bint-14 | CC1: fu-05 | CD1: binf-04 | CE1: fu-18 | CF1: binf-20 | CG1: binf-05 | CH1: ce-08.2 | CI1: baie-15.2 | CJ1: bint-08 | CK1: fu-19.2 | CL1: fu-02 | CM1: fu-04 | CN1: ce-37.2 | CO1: ce-18 | CP1: ce-10 | CQ1: ce-22 | CR1: bint-15 | CS1: bint-02 | CT1: bint-06 | CU1: binf-18.2 | CV1: binf-07 | CW1: binf-12
A2: 0.011 | B2: ='Laser Perc Mass'!B2*VLOOKUP('Laser Perc Mass'!B$1,Tamis!$A$1:$AB$101,28,0) -> 0 | C2: ='Laser Perc Mass'!C2*VLOOKUP('Laser Perc Mass'!C$1,Tamis!$A$1:$AB$101,28,0) -> 0 | D2: ='Laser Perc Mass'!D2*VLOOKUP('Laser Perc Mass'!D$1,Tamis!$A$1:$AB$101,28,0) -> 0 | E2: ='Laser Perc Mass'!E2*VLOOKUP('Laser Perc Mass'!E$1,Tamis!$A$1:$AB$101,28,0) -> 0 | F2: ='Laser Perc Mass'!F2*VLOOKUP('Laser Perc Mass'!F$1,Tamis!$A$1:$AB$101,28,0) -> 0 | G2: ='Laser Perc Mass'!G2*VLOOKUP('Laser Perc Mass'!G$1,Tamis!$A$1:$AB$101,28,0) -> 0 | H2: ='Laser Perc Mass'!H2*VLOOKUP('Laser Perc Mass'!H$1,Tamis!$A$1:$AB$101,28,0) -> 0 | I2: ='Laser Perc Mass'!I2*VLOOKUP('Laser Perc Mass'!I$1,Tamis!$A$1:$AB$101,28,0) -> 0 | ... CW2: ='Laser Perc Mass'!CW2*VLOOKUP('Laser Perc Mass'!CW$1,Tamis!$A$1:$AB$101,28,0) -> 0
A3: 0.013 | B3: ='Laser Perc Mass'!B3*VLOOKUP('Laser Perc Mass'!B$1,Tamis!$A$1:$AB$101,28,0) -> 0 | C3: ='Laser Perc Mass'!C3*VLOOKUP('Laser Perc Mass'!C$1,Tamis!$A$1:$AB$101,28,0) -> 0 | D3: ='Laser Perc Mass'!D3*VLOOKUP('Laser Perc Mass'!D$1,Tamis!$A$1:$AB$101,28,0) -> 0 | E3: ='Laser Perc Mass'!E3*VLOOKUP('Laser Perc Mass'!E$1,Tamis!$A$1:$AB$101,28,0) -> 0 | F3: ='Laser Perc Mass'!F3*VLOOKUP('Laser Perc Mass'!F$1,Tamis!$A$1:$AB$101,28,0) -> 0 | G3: ='Laser Perc Mass'!G3*VLOOKUP('Laser Perc Mass'!G$1,Tamis!$A$1:$AB$101,28,0) -> 0 | H3: ='Laser Perc Mass'!H3*VLOOKUP('Laser Perc Mass'!H$1,Tamis!$A$1:$AB$101,28,0) -> 0 | I3: ='Laser Perc Mass'!I3*VLOOKUP('Laser Perc Mass'!I$1,Tamis!$A$1:$AB$101,28,0) -> 0 | ... CW3: ='Laser Perc Mass'!CW3*VLOOKUP('Laser Perc Mass'!CW$1,Tamis!$A$1:$AB$101,28,0) -> 0
A4: 0.015 | B4: ='Laser Perc Mass'!B4*VLOOKUP('Laser Perc Mass'!B$1,Tamis!$A$1:$AB$101,28,0) -> 0 | C4: ='Laser Perc Mass'!C4*VLOOKUP('Laser Perc Mass'!C$1,Tamis!$A$1:$AB$101,28,0) -> 0 | D4: ='Laser Perc Mass'!D4*VLOOKUP('Laser Perc Mass'!D$1,Tamis!$A$1:$AB$101,28,0) -> 0 | E4: ='Laser Perc Mass'!E4*VLOOKUP('Laser Perc Mass'!E$1,Tamis!$A$1:$AB$101,28,0) -> 0 | F4: ='Laser Perc Mass'!F4*VLOOKUP('Laser Perc Mass'!F$1,Tamis!$A$1:$AB$101,28,0) -> 0 | G4: ='Laser Perc Mass'!G4*VLOOKUP('Laser Perc Mass'!G$1,Tamis!$A$1:$AB$101,28,0) -> 0 | H4: ='Laser Perc Mass'!H4*VLOOKUP('Laser Perc Mass'!H$1,Tamis!$A$1:$AB$101,28,0) -> 0 | I4: ='Laser Perc Mass'!I4*VLOOKUP('Laser Perc Mass'!I$1,Tamis!$A$1:$AB$101,28,0) -> 0 | ... CW4: ='Laser Perc Mass'!CW4*VLOOKUP('Laser Perc Mass'!CW$1,Tamis!$A$1:$AB$101,28,0) -> 0
A5: 0.017 | B5: ='Laser Perc Mass'!B5*VLOOKUP('Laser Perc Mass'!B$1,Tamis!$A$1:$AB$101,28,0) -> 0 | C5: ='Laser Perc Mass'!C5*VLOOKUP('Laser Perc Mass'!C$1,Tamis!$A$1:$AB$101,28,0) -> 0 | D5: ='Laser Perc Mass'!D5*VLOOKUP('Laser Perc Mass'!D$1,Tamis!$A$1:$AB$101,28,0) -> 0 | E5: ='Laser Perc Mass'!E5*VLOOKUP('Laser Perc Mass'!E$1,Tamis!$A$1:$AB$101,28,0) -> 0 | F5: ='Laser Perc Mass'!F5*VLOOKUP('Laser Perc Mass'!F$1,Tamis!$A$1:$AB$101,28,0) -> 0 | G5: ='Laser Perc Mass'!G5*VLOOKUP('Laser Perc Mass'!G$1,Tamis!$A$1:$AB$101,28,0) -> 0 | H5: ='Laser Perc Mass'!H5*VLOOKUP('Laser Perc Mass'!H$1,Tamis!$A$1:$AB$101,28,0) -> 0 | I5: ='Laser Perc Mass'!I5*VLOOKUP('Laser Perc Mass'!I$1,Tamis!$A$1:$AB$101,28,0) -> 0 | ... CW5: ='Laser Perc Mass'!CW5*VLOOKUP('Laser Perc Mass'!CW$1,Tamis!$A$1:$AB$101,28,0) -> 0
A6: 0.02 | B6: ='Laser Perc Mass'!B6*VLOOKUP('Laser Perc Mass'!B$1,Tamis!$A$1:$AB$101,28,0) -> 0 | C6: ='Laser Perc Mass'!C6*VLOOKUP('Laser Perc Mass'!C$1,Tamis!$A$1:$AB$101,28,0) -> 0 | D6: ='Laser Perc Mass'!D6*VLOOKUP('Laser Perc Mass'!D$1,Tamis!$A$1:$AB$101,28,0) -> 0 | E6: ='Laser Perc Mass'!E6*VLOOKUP('Laser Perc Mass'!E$1,Tamis!$A$1:$AB$101,28,0) -> 0 | F6: ='Laser Perc Mass'!F6*VLOOKUP('Laser Perc Mass'!F$1,Tamis!$A$1:$AB$101,28,0) -> 0 | G6: ='Laser Perc Mass'!G6*VLOOKUP('Laser Perc Mass'!G$1,Tamis!$A$1:$AB$101,28,0) -> 0 | H6: ='Laser Perc Mass'!H6*VLOOKUP('Laser Perc Mass'!H$1,Tamis!$A$1:$AB$101,28,0) -> 0 | I6: ='Laser Perc Mass'!I6*VLOOKUP('Laser Perc Mass'!I$1,Tamis!$A$1:$AB$101,28,0) -> 0 | ... CW6: ='Laser Perc Mass'!CW6*VLOOKUP('Laser Perc Mass'!CW$1,Tamis!$A$1:$AB$101,28,0) -> 0
A7: 0.023 | B7: ='Laser Perc Mass'!B7*VLOOKUP('Laser Perc Mass'!B$1,Tamis!$A$1:$AB$101,28,0) -> 0 | C7: ='Laser Perc Mass'!C7*VLOOKUP('Laser Perc Mass'!C$1,Tamis!$A$1:$AB$101,28,0) -> 0 | D7: ='Laser Perc Mass'!D7*VLOOKUP('Laser Perc Mass'!D$1,Tamis!$A$1:$AB$101,28,0) -> 0 | E7: ='Laser Perc Mass'!E7*VLOOKUP('Laser Perc Mass'!E$1,Tamis!$A$1:$AB$101,28,0) -> 0 | F7: ='Laser Perc Mass'!F7*VLOOKUP('Laser Perc Mass'!F$1,Tamis!$A$1:$AB$101,28,0) -> 0 | G7: ='Laser Perc Mass'!G7*VLOOKUP('Laser Perc Mass'!G$1,Tamis!$A$1:$AB$101,28,0) -> 0 | H7: ='Laser Perc Mass'!H7*VLOOKUP('Laser Perc Mass'!H$1,Tamis!$A$1:$AB$101,28,0) -> 0 | I7: ='Laser Perc Mass'!I7*VLOOKUP('Laser Perc Mass'!I$1,Tamis!$A$1:$AB$101,28,0) -> 0 | ... CW7: ='Laser Perc Mass'!CW7*VLOOKUP('Laser Perc Mass'!CW$1,Tamis!$A$1:$AB$101,28,0) -> 0
A8: 0.026 | B8: ='Laser Perc Mass'!B8*VLOOKUP('Laser Perc Mass'!B$1,Tamis!$A$1:$AB$101,28,0) -> 0 | C8: ='Laser Perc Mass'!C8*VLOOKUP('Laser Perc Mass'!C$1,Tamis!$A$1:$AB$101,28,0) -> 0 | D8: ='Laser Perc Mass'!D8*VLOOKUP('Laser Perc Mass'!D$1,Tamis!$A$1:$AB$101,28,0) -> 0 | E8: ='Laser Perc Mass'!E8*VLOOKUP('Laser Perc Mass'!E$1,Tamis!$A$1:$AB$101,28,0) -> 0 | F8: ='Laser Perc Mass'!F8*VLOOKUP('Laser Perc Mass'!F$1,Tamis!$A$1:$AB$101,28,0) -> 0 | G8: ='Laser Perc Mass'!G8*VLOOKUP('Laser Perc Mass'!G$1,Tamis!$A$1:$AB$101,28,0) -> 0 | H8: ='Laser Perc Mass'!H8*VLOOKUP('Laser Perc Mass'!H$1,Tamis!$A$1:$AB$101,28,0) -> 0 | I8: ='Laser Perc Mass'!I8*VLOOKUP('Laser Perc Mass'!I$1,Tamis!$A$1:$AB$101,28,0) -> 0 | ... CW8: ='Laser Perc Mass'!CW8*VLOOKUP('Laser Perc Mass'!CW$1,Tamis!$A$1:$AB$101,28,0) -> 0
A9: 0.03 | B9: ='Laser Perc Mass'!B9*VLOOKUP('Laser Perc Mass'!B$1,Tamis!$A$1:$AB$101,28,0) -> 0 | C9: ='Laser Perc Mass'!C9*VLOOKUP('Laser Perc Mass'!C$1,Tamis!$A$1:$AB$101,28,0) -> 0 | D9: ='Laser Perc Mass'!D9*VLOOKUP('Laser Perc Mass'!D$1,Tamis!$A$1:$AB$101,28,0) -> 0 | E9: ='Laser Perc Mass'!E9*VLOOKUP('Laser Perc Mass'!E$1,Tamis!$A$1:$AB$101,28,0) -> 0 | F9: ='Laser Perc Mass'!F9*VLOOKUP('Laser Perc Mass'!F$1,Tamis!$A$1:$AB$101,28,0) -> 0 | G9: ='Laser Perc Mass'!G9*VLOOKUP('Laser Perc Mass'!G$1,Tamis!$A$1:$AB$101,28,0) -> 0 | H9: ='Laser Perc Mass'!H9*VLOOKUP('Laser Perc Mass'!H$1,Tamis!$A$1:$AB$101,28,0) -> 0 | I9: ='Laser Perc Mass'!I9*VLOOKUP('Laser Perc Mass'!I$1,Tamis!$A$1:$AB$101,28,0) -> 0 | ... CW9: ='Laser Perc Mass'!CW9*VLOOKUP('Laser Perc Mass'!CW$1,Tamis!$A$1:$AB$101,28,0) -> 0
A10: 0.034 | B10: ='Laser Perc Mass'!B10*VLOOKUP('Laser Perc Mass'!B$1,Tamis!$A$1:$AB$101,28,0) -> 0 | C10: ='Laser Perc Mass'!C10*VLOOKUP('Laser Perc Mass'!C$1,Tamis!$A$1:$AB$101,28,0) -> 0 | D10: ='Laser Perc Mass'!D10*VLOOKUP('Laser Perc Mass'!D$1,Tamis!$A$1:$AB$101,28,0) -> 0 | E10: ='Laser Perc Mass'!E10*VLOOKUP('Laser Perc Mass'!E$1,Tamis!$A$1:$AB$101,28,0) -> 0 | F10: ='Laser Perc Mass'!F10*VLOOKUP('Laser Perc Mass'!F$1,Tamis!$A$1:$AB$101,28,0) -> 0 | G10: ='Laser Perc Mass'!G10*VLOOKUP('Laser Perc Mass'!G$1,Tamis!$A$1:$AB$101,28,0) -> 0 | H10: ='Laser Perc Mass'!H10*VLOOKUP('Laser Perc Mass'!H$1,Tamis!$A$1:$AB$101,28,0) -> 0 | I10: ='Laser Perc Mass'!I10*VLOOKUP('Laser Perc Mass'!I$1,Tamis!$A$1:$AB$101,28,0) -> 0 | ... CW10: ='Laser Perc Mass'!CW10*VLOOKUP('Laser Perc Mass'!CW$1,Tamis!$A$1:$AB$101,28,0) -> 0
A11: 0.039 | B11: ='Laser Perc Mass'!B11*VLOOKUP('Laser Perc Mass'!B$1,Tamis!$A$1:$AB$101,28,0) -> 0 | C11: ='Laser Perc Mass'!C11*VLOOKUP('Laser Perc Mass'!C$1,Tamis!$A$1:$AB$101,28,0) -> 0 | D11: ='Laser Perc Mass'!D11*VLOOKUP('Laser Perc Mass'!D$1,Tamis!$A$1:$AB$101,28,0) -> 0 | E11: ='Laser Perc Mass'!E11*VLOOKUP('Laser Perc Mass'!E$1,Tamis!$A$1:$AB$101,28,0) -> 0 | F11: ='Laser Perc Mass'!F11*VLOOKUP('Laser Perc Mass'!F$1,Tamis!$A$1:$AB$101,28,0) -> 0 | G11: ='Laser Perc Mass'!G11*VLOOKUP('Laser Perc Mass'!G$1,Tamis!$A$1:$AB$101,28,0) -> 0 | H11: ='Laser Perc Mass'!H11*VLOOKUP('Laser Perc Mass'!H$1,Tamis!$A$1:$AB$101,28,0) -> 0 | I11: ='Laser Perc Mass'!I11*VLOOKUP('Laser Perc Mass'!I$1,Tamis!$A$1:$AB$101,28,0) -> 0 | ... CW11: ='Laser Perc Mass'!CW11*VLOOKUP('Laser Perc Mass'!CW$1,Tamis!$A$1:$AB$101,28,0) -> 0
A12: 0.044 | B12: ='Laser Perc Mass'!B12*VLOOKUP('Laser Perc Mass'!B$1,Tamis!$A$1:$AB$101,28,0) -> 0 | C12: ='Laser Perc Mass'!C12*VLOOKUP('Laser Perc Mass'!C$1,Tamis!$A$1:$AB$101,28,0) -> 0 | D12: ='Laser Perc Mass'!D12*VLOOKUP('Laser Perc Mass'!D$1,Tamis!$A$1:$AB$101,28,0) -> 0 | E12: ='Laser Perc Mass'!E12*VLOOKUP('Laser Perc Mass'!E$1,Tamis!$A$1:$AB$101,28,0) -> 0 | F12: ='Laser Perc Mass'!F12*VLOOKUP('Laser Perc Mass'!F$1,Tamis!$A$1:$AB$101,28,0) -> 0 | G12: ='Laser Perc Mass'!G12*VLOOKUP('Laser Perc Mass'!G$1,Tamis!$A$1:$AB$101,28,0) -> 0 | H12: ='Laser Perc Mass'!H12*VLOOKUP('Laser Perc Mass'!H$1,Tamis!$A$1:$AB$101,28,0) -> 0 | I12: ='Laser Perc Mass'!I12*VLOOKUP('Laser Perc Mass'!I$1,Tamis!$A$1:$AB$101,28,0) -> 0 | ... CW12: ='Laser Perc Mass'!CW12*VLOOKUP('Laser Perc Mass'!CW$1,Tamis!$A$1:$AB$101,28,0) -> 0
A13: 0.051 | B13: ='Laser Perc Mass'!B13*VLOOKUP('Laser Perc Mass'!B$1,Tamis!$A$1:$AB$101,28,0) -> 0 | C13: ='Laser Perc Mass'!C13*VLOOKUP('Laser Perc Mass'!C$1,Tamis!$A$1:$AB$101,28,0) -> 0 | D13: ='Laser Perc Mass'!D13*VLOOKUP('Laser Perc Mass'!D$1,Tamis!$A$1:$AB$101,28,0) -> 0 | E13: ='Laser Perc Mass'!E13*VLOOKUP('Laser Perc Mass'!E$1,Tamis!$A$1:$AB$101,28,0) -> 0 | F13: ='Laser Perc Mass'!F13*VLOOKUP('Laser Perc Mass'!F$1,Tamis!$A$1:$AB$101,28,0) -> 0 | G13: ='Laser Perc Mass'!G13*VLOOKUP('Laser Perc Mass'!G$1,Tamis!$A$1:$AB$101,28,0) -> 0 | H13: ='Laser Perc Mass'!H13*VLOOKUP('Laser Perc Mass'!H$1,Tamis!$A$1:$AB$101,28,0) -> 0 | I13: ='Laser Perc Mass'!I13*VLOOKUP('Laser Perc Mass'!I$1,Tamis!$A$1:$AB$101,28,0) -> 0 | ... CW13: ='Laser Perc Mass'!CW13*VLOOKUP('Laser Perc Mass'!CW$1,Tamis!$A$1:$AB$101,28,0) -> 0
... A80: 451.556 | B80: ='Laser Perc Mass'!B80*VLOOKUP('Laser Perc Mass'!B$1,Tamis!$A$1:$AB$101,28,0) -> 0 | C80: ='Laser Perc Mass'!C80*VLOOKUP('Laser Perc Mass'!C$1,Tamis!$A$1:$AB$101,28,0) -> 0.56635279 | D80: ='Laser Perc Mass'!D80*VLOOKUP('Laser Perc Mass'!D$1,Tamis!$A$1:$AB$101,28,0) -> 1.8292768 | E80: ='Laser Perc Mass'!E80*VLOOKUP('Laser Perc Mass'!E$1,Tamis!$A$1:$AB$101,28,0) -> 0.26056075 | F80: ='Laser Perc Mass'!F80*VLOOKUP('Laser Perc Mass'!F$1,Tamis!$A$1:$AB$101,28,0) -> 0 | G80: ='Laser Perc Mass'!G80*VLOOKUP('Laser Perc Mass'!G$1,Tamis!$A$1:$AB$101,28,0) -> 0 | H80: ='Laser Perc Mass'!H80*VLOOKUP('Laser Perc Mass'!H$1,Tamis!$A$1:$AB$101,28,0) -> 0 | I80: ='Laser Perc Mass'!I80*VLOOKUP('Laser Perc Mass'!I$1,Tamis!$A$1:$AB$101,28,0) -> 0 | ... CW80: ='Laser Perc Mass'!CW80*VLOOKUP('Laser Perc Mass'!CW$1,Tamis!$A$1:$AB$101,28,0) -> 2.0803733

Sheet Merged
B1: fu-19 | C1: fu-01 | D1: fu-20 | E1: fu-16 | F1: fu-13 | G1: fu-14 | H1: fu-10 | I1: fu-11 | J1: fu-03 | K1: bint-11 | L1: bint-09 | M1: bint-12 | N1: bint-03 | O1: bint-05 | P1: baie-19 | Q1: baie-18 | R1: baie-16 | S1: baie-20 | T1: baie-10 | U1: baie-09 | V1: baie-11 | W1: baie-06 | X1: baie-08 | Y1: baie-04 | Z1: baie-01 | AA1: baie-05 | AB1: baie-02 | AC1: baie-15 | AD1: ce-46 | AE1: ce-47 | AF1: binf-08 | AG1: binf-01 | AH1: ce-50 | AI1: ce-48 | AJ1: binf-18 | AK1: binf-13 | AL1: ce-45 | AM1: binf-17 | AN1: ce-43 | AO1: ce-44 | AP1: ce-40 | AQ1: ce-42 | AR1: ce-37 | AS1: ce-39 | AT1: ce-34 | AU1: ce-36 | AV1: ce-32 | AW1: ce-33 | AX1: ce-30 | AY1: ce-31 | AZ1: ce-27 | BA1: ce-28 | BB1: ce-23 | BC1: ce-25 | BD1: ce-20 | BE1: ce-21 | BF1: ce-15 | BG1: ce-19 | BH1: ce-13 | BI1: ce-08 | BJ1: ce-14 | BK1: ce-06 | BL1: ce-09 | BM1: ce-04 | BN1: ce-07 | BO1: ce-05 | BP1: ce-01 | BQ1: ce-02 | BR1: binf-02 | BS1: ce-51 | BT1: binf-10 | BU1: ce-24 | BV1: binf-15 | BW1: ce-03 | BX1: fu-15 | BY1: ce-12 | BZ1: fu-12 | CA1: ce-16 | CB1: bint-14 | CC1: fu-05 | CD1: binf-04 | CE1: fu-18 | CF1: binf-20 | CG1: binf-05 | CH1: ce-08.2 | CI1: baie-15.2 | CJ1: bint-08 | CK1: fu-19.2 | CL1: fu-02 | CM1: fu-04 | CN1: ce-37.2 | CO1: ce-18 | CP1: ce-10 | CQ1: ce-22 | CR1: bint-15 | CS1: bint-02 | CT1: bint-06 | CU1: binf-18.2 | CV1: binf-07 | CW1: binf-12
A2: 4000 | B2: =VLOOKUP(B$1,Tamis!$A$1:$U$101,16,0) -> 2.5342119 | C2: =VLOOKUP(C$1,Tamis!$A$1:$U$101,16,0) -> 1.5269766 | D2: =VLOOKUP(D$1,Tamis!$A$1:$U$101,16,0) -> 16.112217 | E2: =VLOOKUP(E$1,Tamis!$A$1:$U$101,16,0) -> 7.740086 | F2: =VLOOKUP(F$1,Tamis!$A$1:$U$101,16,0) -> 0 | G2: =VLOOKUP(G$1,Tamis!$A$1:$U$101,16,0) -> 0 | H2: =VLOOKUP(H$1,Tamis!$A$1:$U$101,16,0) -> 0 | I2: =VLOOKUP(I$1,Tamis!$A$1:$U$101,16,0) -> 2.3718172 | ... CW2: =VLOOKUP(CW$1,Tamis!$A$1:$U$101,16,0) -> 0
